2024-12-23 20:24:17,357 INFO    MainThread:42959 [internal.py:wandb_internal():90] W&B internal server running at pid: 42959, started at: 2024-12-23 20:24:17.357136
2024-12-23 20:24:17,359 INFO    WriterThread:42959 [datastore.py:open_for_write():75] open: /home/leobaro/workspace/labs/fair_spoke_8/fair_spoke_8_leonardo/scripts/wandb/run-20241223_202416-1ql4ettk/run-1ql4ettk.wandb
2024-12-23 20:24:17,452 DEBUG   SenderThread:42959 [sender.py:send():236] send: header
2024-12-23 20:24:17,452 DEBUG   SenderThread:42959 [sender.py:send():236] send: run
2024-12-23 20:24:46,981 DEBUG   HandlerThread:42959 [handler.py:handle_request():140] handle_request: shutdown
2024-12-23 20:24:46,982 INFO    HandlerThread:42959 [handler.py:finish():806] shutting down handler
2024-12-23 20:24:47,371 INFO    WriterThread:42959 [datastore.py:close():279] close: /home/leobaro/workspace/labs/fair_spoke_8/fair_spoke_8_leonardo/scripts/wandb/run-20241223_202416-1ql4ettk/run-1ql4ettk.wandb
2024-12-23 20:25:25,932 ERROR   SenderThread:42959 [retry.py:__call__():132] Retry attempt failed:
Traceback (most recent call last):
  File "/home/leobaro/softwares/miniconda3/envs/datacomp/lib/python3.10/site-packages/urllib3/connection.py", line 174, in _new_conn
    conn = connection.create_connection(
  File "/home/leobaro/softwares/miniconda3/envs/datacomp/lib/python3.10/site-packages/urllib3/util/connection.py", line 72, in create_connection
    for res in socket.getaddrinfo(host, port, family, socket.SOCK_STREAM):
  File "/home/leobaro/softwares/miniconda3/envs/datacomp/lib/python3.10/socket.py", line 955, in getaddrinfo
    for res in _socket.getaddrinfo(host, port, family, type, proto, flags):
socket.gaierror: [Errno -3] Temporary failure in name resolution

During handling of the above exception, another exception occurred:

Traceback (most recent call last):
  File "/home/leobaro/softwares/miniconda3/envs/datacomp/lib/python3.10/site-packages/urllib3/connectionpool.py", line 703, in urlopen
    httplib_response = self._make_request(
  File "/home/leobaro/softwares/miniconda3/envs/datacomp/lib/python3.10/site-packages/urllib3/connectionpool.py", line 386, in _make_request
    self._validate_conn(conn)
  File "/home/leobaro/softwares/miniconda3/envs/datacomp/lib/python3.10/site-packages/urllib3/connectionpool.py", line 1042, in _validate_conn
    conn.connect()
  File "/home/leobaro/softwares/miniconda3/envs/datacomp/lib/python3.10/site-packages/urllib3/connection.py", line 358, in connect
    self.sock = conn = self._new_conn()
  File "/home/leobaro/softwares/miniconda3/envs/datacomp/lib/python3.10/site-packages/urllib3/connection.py", line 186, in _new_conn
    raise NewConnectionError(
urllib3.exceptions.NewConnectionError: <urllib3.connection.HTTPSConnection object at 0x70778cf429e0>: Failed to establish a new connection: [Errno -3] Temporary failure in name resolution

During handling of the above exception, another exception occurred:

Traceback (most recent call last):
  File "/home/leobaro/softwares/miniconda3/envs/datacomp/lib/python3.10/site-packages/requests/adapters.py", line 489, in send
    resp = conn.urlopen(
  File "/home/leobaro/softwares/miniconda3/envs/datacomp/lib/python3.10/site-packages/urllib3/connectionpool.py", line 787, in urlopen
    retries = retries.increment(
  File "/home/leobaro/softwares/miniconda3/envs/datacomp/lib/python3.10/site-packages/urllib3/util/retry.py", line 592, in increment
    raise MaxRetryError(_pool, url, error or ResponseError(cause))
urllib3.exceptions.MaxRetryError: HTTPSConnectionPool(host='api.wandb.ai', port=443): Max retries exceeded with url: /graphql (Caused by NewConnectionError('<urllib3.connection.HTTPSConnection object at 0x70778cf429e0>: Failed to establish a new connection: [Errno -3] Temporary failure in name resolution'))

During handling of the above exception, another exception occurred:

Traceback (most recent call last):
  File "/home/leobaro/softwares/miniconda3/envs/datacomp/lib/python3.10/site-packages/wandb/sdk/lib/retry.py", line 108, in __call__
    result = self._call_fn(*args, **kwargs)
  File "/home/leobaro/softwares/miniconda3/envs/datacomp/lib/python3.10/site-packages/wandb/sdk/internal/internal_api.py", line 158, in execute
    return self.client.execute(*args, **kwargs)
  File "/home/leobaro/softwares/miniconda3/envs/datacomp/lib/python3.10/site-packages/wandb/vendor/gql-0.2.0/wandb_gql/client.py", line 52, in execute
    result = self._get_result(document, *args, **kwargs)
  File "/home/leobaro/softwares/miniconda3/envs/datacomp/lib/python3.10/site-packages/wandb/vendor/gql-0.2.0/wandb_gql/client.py", line 60, in _get_result
    return self.transport.execute(document, *args, **kwargs)
  File "/home/leobaro/softwares/miniconda3/envs/datacomp/lib/python3.10/site-packages/wandb/vendor/gql-0.2.0/wandb_gql/transport/requests.py", line 38, in execute
    request = requests.post(self.url, **post_args)
  File "/home/leobaro/softwares/miniconda3/envs/datacomp/lib/python3.10/site-packages/requests/api.py", line 115, in post
    return request("post", url, data=data, json=json, **kwargs)
  File "/home/leobaro/softwares/miniconda3/envs/datacomp/lib/python3.10/site-packages/requests/api.py", line 59, in request
    return session.request(method=method, url=url, **kwargs)
  File "/home/leobaro/softwares/miniconda3/envs/datacomp/lib/python3.10/site-packages/requests/sessions.py", line 587, in request
    resp = self.send(prep, **send_kwargs)
  File "/home/leobaro/softwares/miniconda3/envs/datacomp/lib/python3.10/site-packages/requests/sessions.py", line 701, in send
    r = adapter.send(request, **kwargs)
  File "/home/leobaro/softwares/miniconda3/envs/datacomp/lib/python3.10/site-packages/requests/adapters.py", line 565, in send
    raise ConnectionError(e, request=request)
requests.exceptions.ConnectionError: HTTPSConnectionPool(host='api.wandb.ai', port=443): Max retries exceeded with url: /graphql (Caused by NewConnectionError('<urllib3.connection.HTTPSConnection object at 0x70778cf429e0>: Failed to establish a new connection: [Errno -3] Temporary failure in name resolution'))
2024-12-23 20:29:11,886 INFO    SenderThread:42959 [dir_watcher.py:__init__():216] watching files in: /home/leobaro/workspace/labs/fair_spoke_8/fair_spoke_8_leonardo/scripts/wandb/run-20241223_202416-1ql4ettk/files
2024-12-23 20:29:11,886 INFO    SenderThread:42959 [sender.py:_start_run_threads():815] run started: 1ql4ettk with start time 1734981856
2024-12-23 20:29:11,886 INFO    SenderThread:42959 [sender.py:finish():1114] shutting down sender
2024-12-23 20:29:11,886 INFO    SenderThread:42959 [dir_watcher.py:finish():353] shutting down directory watcher
2024-12-23 20:29:12,887 INFO    SenderThread:42959 [dir_watcher.py:finish():383] scan: /home/leobaro/workspace/labs/fair_spoke_8/fair_spoke_8_leonardo/scripts/wandb/run-20241223_202416-1ql4ettk/files
2024-12-23 20:29:12,887 INFO    SenderThread:42959 [dir_watcher.py:finish():397] scan save: /home/leobaro/workspace/labs/fair_spoke_8/fair_spoke_8_leonardo/scripts/wandb/run-20241223_202416-1ql4ettk/files/config.yaml config.yaml
2024-12-23 20:29:12,887 INFO    SenderThread:42959 [file_pusher.py:finish():171] shutting down file pusher
2024-12-23 20:29:12,887 INFO    SenderThread:42959 [file_pusher.py:join():176] waiting for file pusher
2024-12-23 20:29:36,073 ERROR   Thread-9  :42959 [retry.py:__call__():132] Retry attempt failed:
Traceback (most recent call last):
  File "/home/leobaro/softwares/miniconda3/envs/datacomp/lib/python3.10/site-packages/urllib3/connection.py", line 174, in _new_conn
    conn = connection.create_connection(
  File "/home/leobaro/softwares/miniconda3/envs/datacomp/lib/python3.10/site-packages/urllib3/util/connection.py", line 72, in create_connection
    for res in socket.getaddrinfo(host, port, family, socket.SOCK_STREAM):
  File "/home/leobaro/softwares/miniconda3/envs/datacomp/lib/python3.10/socket.py", line 955, in getaddrinfo
    for res in _socket.getaddrinfo(host, port, family, type, proto, flags):
socket.gaierror: [Errno -3] Temporary failure in name resolution

During handling of the above exception, another exception occurred:

Traceback (most recent call last):
  File "/home/leobaro/softwares/miniconda3/envs/datacomp/lib/python3.10/site-packages/urllib3/connectionpool.py", line 703, in urlopen
    httplib_response = self._make_request(
  File "/home/leobaro/softwares/miniconda3/envs/datacomp/lib/python3.10/site-packages/urllib3/connectionpool.py", line 386, in _make_request
    self._validate_conn(conn)
  File "/home/leobaro/softwares/miniconda3/envs/datacomp/lib/python3.10/site-packages/urllib3/connectionpool.py", line 1042, in _validate_conn
    conn.connect()
  File "/home/leobaro/softwares/miniconda3/envs/datacomp/lib/python3.10/site-packages/urllib3/connection.py", line 358, in connect
    self.sock = conn = self._new_conn()
  File "/home/leobaro/softwares/miniconda3/envs/datacomp/lib/python3.10/site-packages/urllib3/connection.py", line 186, in _new_conn
    raise NewConnectionError(
urllib3.exceptions.NewConnectionError: <urllib3.connection.HTTPSConnection object at 0x707788584760>: Failed to establish a new connection: [Errno -3] Temporary failure in name resolution

During handling of the above exception, another exception occurred:

Traceback (most recent call last):
  File "/home/leobaro/softwares/miniconda3/envs/datacomp/lib/python3.10/site-packages/requests/adapters.py", line 489, in send
    resp = conn.urlopen(
  File "/home/leobaro/softwares/miniconda3/envs/datacomp/lib/python3.10/site-packages/urllib3/connectionpool.py", line 787, in urlopen
    retries = retries.increment(
  File "/home/leobaro/softwares/miniconda3/envs/datacomp/lib/python3.10/site-packages/urllib3/util/retry.py", line 592, in increment
    raise MaxRetryError(_pool, url, error or ResponseError(cause))
urllib3.exceptions.MaxRetryError: HTTPSConnectionPool(host='api.wandb.ai', port=443): Max retries exceeded with url: /graphql (Caused by NewConnectionError('<urllib3.connection.HTTPSConnection object at 0x707788584760>: Failed to establish a new connection: [Errno -3] Temporary failure in name resolution'))

During handling of the above exception, another exception occurred:

Traceback (most recent call last):
  File "/home/leobaro/softwares/miniconda3/envs/datacomp/lib/python3.10/site-packages/wandb/sdk/lib/retry.py", line 108, in __call__
    result = self._call_fn(*args, **kwargs)
  File "/home/leobaro/softwares/miniconda3/envs/datacomp/lib/python3.10/site-packages/wandb/sdk/internal/internal_api.py", line 158, in execute
    return self.client.execute(*args, **kwargs)
  File "/home/leobaro/softwares/miniconda3/envs/datacomp/lib/python3.10/site-packages/wandb/vendor/gql-0.2.0/wandb_gql/client.py", line 52, in execute
    result = self._get_result(document, *args, **kwargs)
  File "/home/leobaro/softwares/miniconda3/envs/datacomp/lib/python3.10/site-packages/wandb/vendor/gql-0.2.0/wandb_gql/client.py", line 60, in _get_result
    return self.transport.execute(document, *args, **kwargs)
  File "/home/leobaro/softwares/miniconda3/envs/datacomp/lib/python3.10/site-packages/wandb/vendor/gql-0.2.0/wandb_gql/transport/requests.py", line 38, in execute
    request = requests.post(self.url, **post_args)
  File "/home/leobaro/softwares/miniconda3/envs/datacomp/lib/python3.10/site-packages/requests/api.py", line 115, in post
    return request("post", url, data=data, json=json, **kwargs)
  File "/home/leobaro/softwares/miniconda3/envs/datacomp/lib/python3.10/site-packages/requests/api.py", line 59, in request
    return session.request(method=method, url=url, **kwargs)
  File "/home/leobaro/softwares/miniconda3/envs/datacomp/lib/python3.10/site-packages/requests/sessions.py", line 587, in request
    resp = self.send(prep, **send_kwargs)
  File "/home/leobaro/softwares/miniconda3/envs/datacomp/lib/python3.10/site-packages/requests/sessions.py", line 701, in send
    r = adapter.send(request, **kwargs)
  File "/home/leobaro/softwares/miniconda3/envs/datacomp/lib/python3.10/site-packages/requests/adapters.py", line 565, in send
    raise ConnectionError(e, request=request)
requests.exceptions.ConnectionError: HTTPSConnectionPool(host='api.wandb.ai', port=443): Max retries exceeded with url: /graphql (Caused by NewConnectionError('<urllib3.connection.HTTPSConnection object at 0x707788584760>: Failed to establish a new connection: [Errno -3] Temporary failure in name resolution'))
2024-12-23 20:30:11,905 WARNING FileStreamThread:42959 [file_stream.py:request_with_retry():589] requests_with_retry encountered retryable exception: HTTPSConnectionPool(host='api.wandb.ai', port=443): Max retries exceeded with url: /files/leobaro/datacomp/1ql4ettk/file_stream (Caused by NewConnectionError('<urllib3.connection.HTTPSConnection object at 0x707788584d60>: Failed to establish a new connection: [Errno -3] Temporary failure in name resolution')). func: <bound method Session.post of <requests.sessions.Session object at 0x70778cf07c40>>, args: ('https://api.wandb.ai/files/leobaro/datacomp/1ql4ettk/file_stream',), kwargs: {'json': {'complete': False, 'failed': False, 'dropped': 0, 'uploaded': []}}
2024-12-23 20:30:14,405 WARNING FileStreamThread:42959 [file_stream.py:request_with_retry():589] requests_with_retry encountered retryable exception: HTTPSConnectionPool(host='api.wandb.ai', port=443): Max retries exceeded with url: /files/leobaro/datacomp/1ql4ettk/file_stream (Caused by NewConnectionError('<urllib3.connection.HTTPSConnection object at 0x70778855b400>: Failed to establish a new connection: [Errno -3] Temporary failure in name resolution')). func: <bound method Session.post of <requests.sessions.Session object at 0x70778cf07c40>>, args: ('https://api.wandb.ai/files/leobaro/datacomp/1ql4ettk/file_stream',), kwargs: {'json': {'complete': False, 'failed': False, 'dropped': 0, 'uploaded': []}}
2024-12-23 20:30:33,033 WARNING FileStreamThread:42959 [file_stream.py:request_with_retry():589] requests_with_retry encountered retryable exception: HTTPSConnectionPool(host='api.wandb.ai', port=443): Max retries exceeded with url: /files/leobaro/datacomp/1ql4ettk/file_stream (Caused by NewConnectionError('<urllib3.connection.HTTPSConnection object at 0x70778855b790>: Failed to establish a new connection: [Errno 111] Connection refused')). func: <bound method Session.post of <requests.sessions.Session object at 0x70778cf07c40>>, args: ('https://api.wandb.ai/files/leobaro/datacomp/1ql4ettk/file_stream',), kwargs: {'json': {'complete': False, 'failed': False, 'dropped': 0, 'uploaded': []}}
2024-12-23 20:30:42,603 WARNING FileStreamThread:42959 [file_stream.py:request_with_retry():589] requests_with_retry encountered retryable exception: HTTPSConnectionPool(host='api.wandb.ai', port=443): Max retries exceeded with url: /files/leobaro/datacomp/1ql4ettk/file_stream (Caused by NewConnectionError('<urllib3.connection.HTTPSConnection object at 0x707788584fa0>: Failed to establish a new connection: [Errno -3] Temporary failure in name resolution')). func: <bound method Session.post of <requests.sessions.Session object at 0x70778cf07c40>>, args: ('https://api.wandb.ai/files/leobaro/datacomp/1ql4ettk/file_stream',), kwargs: {'json': {'complete': False, 'failed': False, 'dropped': 0, 'uploaded': []}}
2024-12-23 20:31:01,177 WARNING FileStreamThread:42959 [file_stream.py:request_with_retry():589] requests_with_retry encountered retryable exception: HTTPSConnectionPool(host='api.wandb.ai', port=443): Max retries exceeded with url: /files/leobaro/datacomp/1ql4ettk/file_stream (Caused by NewConnectionError('<urllib3.connection.HTTPSConnection object at 0x707788584f40>: Failed to establish a new connection: [Errno -3] Temporary failure in name resolution')). func: <bound method Session.post of <requests.sessions.Session object at 0x70778cf07c40>>, args: ('https://api.wandb.ai/files/leobaro/datacomp/1ql4ettk/file_stream',), kwargs: {'json': {'complete': False, 'failed': False, 'dropped': 0, 'uploaded': []}}
2024-12-23 20:31:38,026 WARNING FileStreamThread:42959 [file_stream.py:request_with_retry():589] requests_with_retry encountered retryable exception: HTTPSConnectionPool(host='api.wandb.ai', port=443): Max retries exceeded with url: /files/leobaro/datacomp/1ql4ettk/file_stream (Caused by NewConnectionError('<urllib3.connection.HTTPSConnection object at 0x707788584fa0>: Failed to establish a new connection: [Errno -3] Temporary failure in name resolution')). func: <bound method Session.post of <requests.sessions.Session object at 0x70778cf07c40>>, args: ('https://api.wandb.ai/files/leobaro/datacomp/1ql4ettk/file_stream',), kwargs: {'json': {'complete': False, 'failed': False, 'dropped': 0, 'uploaded': []}}
2024-12-23 20:32:59,033 WARNING FileStreamThread:42959 [file_stream.py:request_with_retry():589] requests_with_retry encountered retryable exception: HTTPSConnectionPool(host='api.wandb.ai', port=443): Max retries exceeded with url: /files/leobaro/datacomp/1ql4ettk/file_stream (Caused by NewConnectionError('<urllib3.connection.HTTPSConnection object at 0x707788584eb0>: Failed to establish a new connection: [Errno -3] Temporary failure in name resolution')). func: <bound method Session.post of <requests.sessions.Session object at 0x70778cf07c40>>, args: ('https://api.wandb.ai/files/leobaro/datacomp/1ql4ettk/file_stream',), kwargs: {'json': {'complete': False, 'failed': False, 'dropped': 0, 'uploaded': []}}
2024-12-23 20:35:33,440 ERROR   Thread-9  :42959 [internal_api.py:upload_file():1694] upload_file exception https://storage.googleapis.com/wandb-production.appspot.com/leobaro/datacomp/1ql4ettk/config.yaml?Expires=1735068918&GoogleAccessId=gorilla-files-url-signer-man%40wandb-production.iam.gserviceaccount.com&Signature=FGSC4lGNweshlGOVlc%2BJ5L8jwCN%2B2sDS3UGnMovoMoDPNXZKBQC4DqsitbxzXskQCxw31OBjuhqi%2BA63JYCgQcQAyDWT9aPmXSD26Z1Mj%2FY3E9qP%2FvtBi7D4A7PCR9tOWsbIJbZO4p44gi%2BKbes38dZcs9WXQGjKE7ZtiGc%2FfViWD1ycg4aIJqbmeb%2BlqfIFFRK7QmqkAT1QswiLO1FPtx9BLdGXKlhf9%2B2BquKpmTm5z031Ek7xTFx8R8juSwYABRcLRPR6C7LFvA5iG7jjyGx4hzQsnkyV7hzwKBghnah0TSaTxMA8qCY%2FhTcYv8DlLG8EPGvW9ucYCT%2BafoRIVg%3D%3D: HTTPSConnectionPool(host='storage.googleapis.com', port=443): Max retries exceeded with url: /wandb-production.appspot.com/leobaro/datacomp/1ql4ettk/config.yaml?Expires=1735068918&GoogleAccessId=gorilla-files-url-signer-man%40wandb-production.iam.gserviceaccount.com&Signature=FGSC4lGNweshlGOVlc%2BJ5L8jwCN%2B2sDS3UGnMovoMoDPNXZKBQC4DqsitbxzXskQCxw31OBjuhqi%2BA63JYCgQcQAyDWT9aPmXSD26Z1Mj%2FY3E9qP%2FvtBi7D4A7PCR9tOWsbIJbZO4p44gi%2BKbes38dZcs9WXQGjKE7ZtiGc%2FfViWD1ycg4aIJqbmeb%2BlqfIFFRK7QmqkAT1QswiLO1FPtx9BLdGXKlhf9%2B2BquKpmTm5z031Ek7xTFx8R8juSwYABRcLRPR6C7LFvA5iG7jjyGx4hzQsnkyV7hzwKBghnah0TSaTxMA8qCY%2FhTcYv8DlLG8EPGvW9ucYCT%2BafoRIVg%3D%3D (Caused by NewConnectionError('<urllib3.connection.HTTPSConnection object at 0x7077885841c0>: Failed to establish a new connection: [Errno 111] Connection refused'))
2024-12-23 20:35:33,440 ERROR   Thread-9  :42959 [internal_api.py:upload_file():1696] upload_file request headers: {'User-Agent': 'python-requests/2.28.1', 'Accept-Encoding': 'gzip, deflate', 'Accept': '*/*', 'Connection': 'keep-alive', 'Content-Length': '2105'}
2024-12-23 20:35:33,440 ERROR   Thread-9  :42959 [internal_api.py:upload_file():1698] upload_file response body: 
2024-12-23 20:35:40,045 WARNING FileStreamThread:42959 [file_stream.py:request_with_retry():589] requests_with_retry encountered retryable exception: HTTPSConnectionPool(host='api.wandb.ai', port=443): Max retries exceeded with url: /files/leobaro/datacomp/1ql4ettk/file_stream (Caused by NewConnectionError('<urllib3.connection.HTTPSConnection object at 0x707788584fa0>: Failed to establish a new connection: [Errno -3] Temporary failure in name resolution')). func: <bound method Session.post of <requests.sessions.Session object at 0x70778cf07c40>>, args: ('https://api.wandb.ai/files/leobaro/datacomp/1ql4ettk/file_stream',), kwargs: {'json': {'complete': False, 'failed': False, 'dropped': 0, 'uploaded': []}}
2024-12-23 20:35:54,567 ERROR   Thread-9  :42959 [internal_api.py:upload_file():1694] upload_file exception https://storage.googleapis.com/wandb-production.appspot.com/leobaro/datacomp/1ql4ettk/config.yaml?Expires=1735068918&GoogleAccessId=gorilla-files-url-signer-man%40wandb-production.iam.gserviceaccount.com&Signature=FGSC4lGNweshlGOVlc%2BJ5L8jwCN%2B2sDS3UGnMovoMoDPNXZKBQC4DqsitbxzXskQCxw31OBjuhqi%2BA63JYCgQcQAyDWT9aPmXSD26Z1Mj%2FY3E9qP%2FvtBi7D4A7PCR9tOWsbIJbZO4p44gi%2BKbes38dZcs9WXQGjKE7ZtiGc%2FfViWD1ycg4aIJqbmeb%2BlqfIFFRK7QmqkAT1QswiLO1FPtx9BLdGXKlhf9%2B2BquKpmTm5z031Ek7xTFx8R8juSwYABRcLRPR6C7LFvA5iG7jjyGx4hzQsnkyV7hzwKBghnah0TSaTxMA8qCY%2FhTcYv8DlLG8EPGvW9ucYCT%2BafoRIVg%3D%3D: HTTPSConnectionPool(host='storage.googleapis.com', port=443): Max retries exceeded with url: /wandb-production.appspot.com/leobaro/datacomp/1ql4ettk/config.yaml?Expires=1735068918&GoogleAccessId=gorilla-files-url-signer-man%40wandb-production.iam.gserviceaccount.com&Signature=FGSC4lGNweshlGOVlc%2BJ5L8jwCN%2B2sDS3UGnMovoMoDPNXZKBQC4DqsitbxzXskQCxw31OBjuhqi%2BA63JYCgQcQAyDWT9aPmXSD26Z1Mj%2FY3E9qP%2FvtBi7D4A7PCR9tOWsbIJbZO4p44gi%2BKbes38dZcs9WXQGjKE7ZtiGc%2FfViWD1ycg4aIJqbmeb%2BlqfIFFRK7QmqkAT1QswiLO1FPtx9BLdGXKlhf9%2B2BquKpmTm5z031Ek7xTFx8R8juSwYABRcLRPR6C7LFvA5iG7jjyGx4hzQsnkyV7hzwKBghnah0TSaTxMA8qCY%2FhTcYv8DlLG8EPGvW9ucYCT%2BafoRIVg%3D%3D (Caused by NewConnectionError('<urllib3.connection.HTTPSConnection object at 0x7077885860b0>: Failed to establish a new connection: [Errno -3] Temporary failure in name resolution'))
2024-12-23 20:35:54,567 ERROR   Thread-9  :42959 [internal_api.py:upload_file():1696] upload_file request headers: {'User-Agent': 'python-requests/2.28.1', 'Accept-Encoding': 'gzip, deflate', 'Accept': '*/*', 'Connection': 'keep-alive', 'Content-Length': '2105'}
2024-12-23 20:35:54,567 ERROR   Thread-9  :42959 [internal_api.py:upload_file():1698] upload_file response body: 
2024-12-23 20:36:17,007 ERROR   Thread-9  :42959 [internal_api.py:upload_file():1694] upload_file exception https://storage.googleapis.com/wandb-production.appspot.com/leobaro/datacomp/1ql4ettk/config.yaml?Expires=1735068918&GoogleAccessId=gorilla-files-url-signer-man%40wandb-production.iam.gserviceaccount.com&Signature=FGSC4lGNweshlGOVlc%2BJ5L8jwCN%2B2sDS3UGnMovoMoDPNXZKBQC4DqsitbxzXskQCxw31OBjuhqi%2BA63JYCgQcQAyDWT9aPmXSD26Z1Mj%2FY3E9qP%2FvtBi7D4A7PCR9tOWsbIJbZO4p44gi%2BKbes38dZcs9WXQGjKE7ZtiGc%2FfViWD1ycg4aIJqbmeb%2BlqfIFFRK7QmqkAT1QswiLO1FPtx9BLdGXKlhf9%2B2BquKpmTm5z031Ek7xTFx8R8juSwYABRcLRPR6C7LFvA5iG7jjyGx4hzQsnkyV7hzwKBghnah0TSaTxMA8qCY%2FhTcYv8DlLG8EPGvW9ucYCT%2BafoRIVg%3D%3D: HTTPSConnectionPool(host='storage.googleapis.com', port=443): Max retries exceeded with url: /wandb-production.appspot.com/leobaro/datacomp/1ql4ettk/config.yaml?Expires=1735068918&GoogleAccessId=gorilla-files-url-signer-man%40wandb-production.iam.gserviceaccount.com&Signature=FGSC4lGNweshlGOVlc%2BJ5L8jwCN%2B2sDS3UGnMovoMoDPNXZKBQC4DqsitbxzXskQCxw31OBjuhqi%2BA63JYCgQcQAyDWT9aPmXSD26Z1Mj%2FY3E9qP%2FvtBi7D4A7PCR9tOWsbIJbZO4p44gi%2BKbes38dZcs9WXQGjKE7ZtiGc%2FfViWD1ycg4aIJqbmeb%2BlqfIFFRK7QmqkAT1QswiLO1FPtx9BLdGXKlhf9%2B2BquKpmTm5z031Ek7xTFx8R8juSwYABRcLRPR6C7LFvA5iG7jjyGx4hzQsnkyV7hzwKBghnah0TSaTxMA8qCY%2FhTcYv8DlLG8EPGvW9ucYCT%2BafoRIVg%3D%3D (Caused by NewConnectionError('<urllib3.connection.HTTPSConnection object at 0x707788586410>: Failed to establish a new connection: [Errno -3] Temporary failure in name resolution'))
2024-12-23 20:36:17,007 ERROR   Thread-9  :42959 [internal_api.py:upload_file():1696] upload_file request headers: {'User-Agent': 'python-requests/2.28.1', 'Accept-Encoding': 'gzip, deflate', 'Accept': '*/*', 'Connection': 'keep-alive', 'Content-Length': '2105'}
2024-12-23 20:36:17,007 ERROR   Thread-9  :42959 [internal_api.py:upload_file():1698] upload_file response body: 
2024-12-23 20:36:17,007 ERROR   Thread-9  :42959 [retry.py:__call__():132] Retry attempt failed:
Traceback (most recent call last):
  File "/home/leobaro/softwares/miniconda3/envs/datacomp/lib/python3.10/site-packages/urllib3/connection.py", line 174, in _new_conn
    conn = connection.create_connection(
  File "/home/leobaro/softwares/miniconda3/envs/datacomp/lib/python3.10/site-packages/urllib3/util/connection.py", line 72, in create_connection
    for res in socket.getaddrinfo(host, port, family, socket.SOCK_STREAM):
  File "/home/leobaro/softwares/miniconda3/envs/datacomp/lib/python3.10/socket.py", line 955, in getaddrinfo
    for res in _socket.getaddrinfo(host, port, family, type, proto, flags):
socket.gaierror: [Errno -3] Temporary failure in name resolution

During handling of the above exception, another exception occurred:

Traceback (most recent call last):
  File "/home/leobaro/softwares/miniconda3/envs/datacomp/lib/python3.10/site-packages/urllib3/connectionpool.py", line 703, in urlopen
    httplib_response = self._make_request(
  File "/home/leobaro/softwares/miniconda3/envs/datacomp/lib/python3.10/site-packages/urllib3/connectionpool.py", line 386, in _make_request
    self._validate_conn(conn)
  File "/home/leobaro/softwares/miniconda3/envs/datacomp/lib/python3.10/site-packages/urllib3/connectionpool.py", line 1042, in _validate_conn
    conn.connect()
  File "/home/leobaro/softwares/miniconda3/envs/datacomp/lib/python3.10/site-packages/urllib3/connection.py", line 358, in connect
    self.sock = conn = self._new_conn()
  File "/home/leobaro/softwares/miniconda3/envs/datacomp/lib/python3.10/site-packages/urllib3/connection.py", line 186, in _new_conn
    raise NewConnectionError(
urllib3.exceptions.NewConnectionError: <urllib3.connection.HTTPSConnection object at 0x707788586410>: Failed to establish a new connection: [Errno -3] Temporary failure in name resolution

During handling of the above exception, another exception occurred:

Traceback (most recent call last):
  File "/home/leobaro/softwares/miniconda3/envs/datacomp/lib/python3.10/site-packages/requests/adapters.py", line 489, in send
    resp = conn.urlopen(
  File "/home/leobaro/softwares/miniconda3/envs/datacomp/lib/python3.10/site-packages/urllib3/connectionpool.py", line 787, in urlopen
    retries = retries.increment(
  File "/home/leobaro/softwares/miniconda3/envs/datacomp/lib/python3.10/site-packages/urllib3/util/retry.py", line 592, in increment
    raise MaxRetryError(_pool, url, error or ResponseError(cause))
urllib3.exceptions.MaxRetryError: HTTPSConnectionPool(host='storage.googleapis.com', port=443): Max retries exceeded with url: /wandb-production.appspot.com/leobaro/datacomp/1ql4ettk/config.yaml?Expires=1735068918&GoogleAccessId=gorilla-files-url-signer-man%40wandb-production.iam.gserviceaccount.com&Signature=FGSC4lGNweshlGOVlc%2BJ5L8jwCN%2B2sDS3UGnMovoMoDPNXZKBQC4DqsitbxzXskQCxw31OBjuhqi%2BA63JYCgQcQAyDWT9aPmXSD26Z1Mj%2FY3E9qP%2FvtBi7D4A7PCR9tOWsbIJbZO4p44gi%2BKbes38dZcs9WXQGjKE7ZtiGc%2FfViWD1ycg4aIJqbmeb%2BlqfIFFRK7QmqkAT1QswiLO1FPtx9BLdGXKlhf9%2B2BquKpmTm5z031Ek7xTFx8R8juSwYABRcLRPR6C7LFvA5iG7jjyGx4hzQsnkyV7hzwKBghnah0TSaTxMA8qCY%2FhTcYv8DlLG8EPGvW9ucYCT%2BafoRIVg%3D%3D (Caused by NewConnectionError('<urllib3.connection.HTTPSConnection object at 0x707788586410>: Failed to establish a new connection: [Errno -3] Temporary failure in name resolution'))

During handling of the above exception, another exception occurred:

Traceback (most recent call last):
  File "/home/leobaro/softwares/miniconda3/envs/datacomp/lib/python3.10/site-packages/wandb/sdk/internal/internal_api.py", line 1691, in upload_file
    response = requests.put(url, data=progress, headers=extra_headers)
  File "/home/leobaro/softwares/miniconda3/envs/datacomp/lib/python3.10/site-packages/requests/api.py", line 130, in put
    return request("put", url, data=data, **kwargs)
  File "/home/leobaro/softwares/miniconda3/envs/datacomp/lib/python3.10/site-packages/requests/api.py", line 59, in request
    return session.request(method=method, url=url, **kwargs)
  File "/home/leobaro/softwares/miniconda3/envs/datacomp/lib/python3.10/site-packages/requests/sessions.py", line 587, in request
    resp = self.send(prep, **send_kwargs)
  File "/home/leobaro/softwares/miniconda3/envs/datacomp/lib/python3.10/site-packages/requests/sessions.py", line 701, in send
    r = adapter.send(request, **kwargs)
  File "/home/leobaro/softwares/miniconda3/envs/datacomp/lib/python3.10/site-packages/requests/adapters.py", line 565, in send
    raise ConnectionError(e, request=request)
requests.exceptions.ConnectionError: HTTPSConnectionPool(host='storage.googleapis.com', port=443): Max retries exceeded with url: /wandb-production.appspot.com/leobaro/datacomp/1ql4ettk/config.yaml?Expires=1735068918&GoogleAccessId=gorilla-files-url-signer-man%40wandb-production.iam.gserviceaccount.com&Signature=FGSC4lGNweshlGOVlc%2BJ5L8jwCN%2B2sDS3UGnMovoMoDPNXZKBQC4DqsitbxzXskQCxw31OBjuhqi%2BA63JYCgQcQAyDWT9aPmXSD26Z1Mj%2FY3E9qP%2FvtBi7D4A7PCR9tOWsbIJbZO4p44gi%2BKbes38dZcs9WXQGjKE7ZtiGc%2FfViWD1ycg4aIJqbmeb%2BlqfIFFRK7QmqkAT1QswiLO1FPtx9BLdGXKlhf9%2B2BquKpmTm5z031Ek7xTFx8R8juSwYABRcLRPR6C7LFvA5iG7jjyGx4hzQsnkyV7hzwKBghnah0TSaTxMA8qCY%2FhTcYv8DlLG8EPGvW9ucYCT%2BafoRIVg%3D%3D (Caused by NewConnectionError('<urllib3.connection.HTTPSConnection object at 0x707788586410>: Failed to establish a new connection: [Errno -3] Temporary failure in name resolution'))

During handling of the above exception, another exception occurred:

Traceback (most recent call last):
  File "/home/leobaro/softwares/miniconda3/envs/datacomp/lib/python3.10/site-packages/wandb/sdk/lib/retry.py", line 108, in __call__
    result = self._call_fn(*args, **kwargs)
  File "/home/leobaro/softwares/miniconda3/envs/datacomp/lib/python3.10/site-packages/wandb/sdk/internal/internal_api.py", line 1707, in upload_file
    raise e.with_traceback(sys.exc_info()[2])
  File "/home/leobaro/softwares/miniconda3/envs/datacomp/lib/python3.10/site-packages/wandb/sdk/internal/internal_api.py", line 1691, in upload_file
    response = requests.put(url, data=progress, headers=extra_headers)
  File "/home/leobaro/softwares/miniconda3/envs/datacomp/lib/python3.10/site-packages/requests/api.py", line 130, in put
    return request("put", url, data=data, **kwargs)
  File "/home/leobaro/softwares/miniconda3/envs/datacomp/lib/python3.10/site-packages/requests/api.py", line 59, in request
    return session.request(method=method, url=url, **kwargs)
  File "/home/leobaro/softwares/miniconda3/envs/datacomp/lib/python3.10/site-packages/requests/sessions.py", line 587, in request
    resp = self.send(prep, **send_kwargs)
  File "/home/leobaro/softwares/miniconda3/envs/datacomp/lib/python3.10/site-packages/requests/sessions.py", line 701, in send
    r = adapter.send(request, **kwargs)
  File "/home/leobaro/softwares/miniconda3/envs/datacomp/lib/python3.10/site-packages/requests/adapters.py", line 565, in send
    raise ConnectionError(e, request=request)
wandb.sdk.lib.retry.TransientError: None
2024-12-23 20:36:41,734 ERROR   Thread-9  :42959 [internal_api.py:upload_file():1694] upload_file exception https://storage.googleapis.com/wandb-production.appspot.com/leobaro/datacomp/1ql4ettk/config.yaml?Expires=1735068918&GoogleAccessId=gorilla-files-url-signer-man%40wandb-production.iam.gserviceaccount.com&Signature=FGSC4lGNweshlGOVlc%2BJ5L8jwCN%2B2sDS3UGnMovoMoDPNXZKBQC4DqsitbxzXskQCxw31OBjuhqi%2BA63JYCgQcQAyDWT9aPmXSD26Z1Mj%2FY3E9qP%2FvtBi7D4A7PCR9tOWsbIJbZO4p44gi%2BKbes38dZcs9WXQGjKE7ZtiGc%2FfViWD1ycg4aIJqbmeb%2BlqfIFFRK7QmqkAT1QswiLO1FPtx9BLdGXKlhf9%2B2BquKpmTm5z031Ek7xTFx8R8juSwYABRcLRPR6C7LFvA5iG7jjyGx4hzQsnkyV7hzwKBghnah0TSaTxMA8qCY%2FhTcYv8DlLG8EPGvW9ucYCT%2BafoRIVg%3D%3D: HTTPSConnectionPool(host='storage.googleapis.com', port=443): Max retries exceeded with url: /wandb-production.appspot.com/leobaro/datacomp/1ql4ettk/config.yaml?Expires=1735068918&GoogleAccessId=gorilla-files-url-signer-man%40wandb-production.iam.gserviceaccount.com&Signature=FGSC4lGNweshlGOVlc%2BJ5L8jwCN%2B2sDS3UGnMovoMoDPNXZKBQC4DqsitbxzXskQCxw31OBjuhqi%2BA63JYCgQcQAyDWT9aPmXSD26Z1Mj%2FY3E9qP%2FvtBi7D4A7PCR9tOWsbIJbZO4p44gi%2BKbes38dZcs9WXQGjKE7ZtiGc%2FfViWD1ycg4aIJqbmeb%2BlqfIFFRK7QmqkAT1QswiLO1FPtx9BLdGXKlhf9%2B2BquKpmTm5z031Ek7xTFx8R8juSwYABRcLRPR6C7LFvA5iG7jjyGx4hzQsnkyV7hzwKBghnah0TSaTxMA8qCY%2FhTcYv8DlLG8EPGvW9ucYCT%2BafoRIVg%3D%3D (Caused by NewConnectionError('<urllib3.connection.HTTPSConnection object at 0x707788585ff0>: Failed to establish a new connection: [Errno -3] Temporary failure in name resolution'))
2024-12-23 20:36:41,734 ERROR   Thread-9  :42959 [internal_api.py:upload_file():1696] upload_file request headers: {'User-Agent': 'python-requests/2.28.1', 'Accept-Encoding': 'gzip, deflate', 'Accept': '*/*', 'Connection': 'keep-alive', 'Content-Length': '2105'}
2024-12-23 20:36:41,734 ERROR   Thread-9  :42959 [internal_api.py:upload_file():1698] upload_file response body: 
2024-12-23 20:37:10,719 ERROR   Thread-9  :42959 [internal_api.py:upload_file():1694] upload_file exception https://storage.googleapis.com/wandb-production.appspot.com/leobaro/datacomp/1ql4ettk/config.yaml?Expires=1735068918&GoogleAccessId=gorilla-files-url-signer-man%40wandb-production.iam.gserviceaccount.com&Signature=FGSC4lGNweshlGOVlc%2BJ5L8jwCN%2B2sDS3UGnMovoMoDPNXZKBQC4DqsitbxzXskQCxw31OBjuhqi%2BA63JYCgQcQAyDWT9aPmXSD26Z1Mj%2FY3E9qP%2FvtBi7D4A7PCR9tOWsbIJbZO4p44gi%2BKbes38dZcs9WXQGjKE7ZtiGc%2FfViWD1ycg4aIJqbmeb%2BlqfIFFRK7QmqkAT1QswiLO1FPtx9BLdGXKlhf9%2B2BquKpmTm5z031Ek7xTFx8R8juSwYABRcLRPR6C7LFvA5iG7jjyGx4hzQsnkyV7hzwKBghnah0TSaTxMA8qCY%2FhTcYv8DlLG8EPGvW9ucYCT%2BafoRIVg%3D%3D: HTTPSConnectionPool(host='storage.googleapis.com', port=443): Max retries exceeded with url: /wandb-production.appspot.com/leobaro/datacomp/1ql4ettk/config.yaml?Expires=1735068918&GoogleAccessId=gorilla-files-url-signer-man%40wandb-production.iam.gserviceaccount.com&Signature=FGSC4lGNweshlGOVlc%2BJ5L8jwCN%2B2sDS3UGnMovoMoDPNXZKBQC4DqsitbxzXskQCxw31OBjuhqi%2BA63JYCgQcQAyDWT9aPmXSD26Z1Mj%2FY3E9qP%2FvtBi7D4A7PCR9tOWsbIJbZO4p44gi%2BKbes38dZcs9WXQGjKE7ZtiGc%2FfViWD1ycg4aIJqbmeb%2BlqfIFFRK7QmqkAT1QswiLO1FPtx9BLdGXKlhf9%2B2BquKpmTm5z031Ek7xTFx8R8juSwYABRcLRPR6C7LFvA5iG7jjyGx4hzQsnkyV7hzwKBghnah0TSaTxMA8qCY%2FhTcYv8DlLG8EPGvW9ucYCT%2BafoRIVg%3D%3D (Caused by NewConnectionError('<urllib3.connection.HTTPSConnection object at 0x7077885861a0>: Failed to establish a new connection: [Errno -3] Temporary failure in name resolution'))
2024-12-23 20:37:10,720 ERROR   Thread-9  :42959 [internal_api.py:upload_file():1696] upload_file request headers: {'User-Agent': 'python-requests/2.28.1', 'Accept-Encoding': 'gzip, deflate', 'Accept': '*/*', 'Connection': 'keep-alive', 'Content-Length': '2105'}
2024-12-23 20:37:10,720 ERROR   Thread-9  :42959 [internal_api.py:upload_file():1698] upload_file response body: 
2024-12-23 20:37:50,338 ERROR   Thread-9  :42959 [internal_api.py:upload_file():1694] upload_file exception https://storage.googleapis.com/wandb-production.appspot.com/leobaro/datacomp/1ql4ettk/config.yaml?Expires=1735068918&GoogleAccessId=gorilla-files-url-signer-man%40wandb-production.iam.gserviceaccount.com&Signature=FGSC4lGNweshlGOVlc%2BJ5L8jwCN%2B2sDS3UGnMovoMoDPNXZKBQC4DqsitbxzXskQCxw31OBjuhqi%2BA63JYCgQcQAyDWT9aPmXSD26Z1Mj%2FY3E9qP%2FvtBi7D4A7PCR9tOWsbIJbZO4p44gi%2BKbes38dZcs9WXQGjKE7ZtiGc%2FfViWD1ycg4aIJqbmeb%2BlqfIFFRK7QmqkAT1QswiLO1FPtx9BLdGXKlhf9%2B2BquKpmTm5z031Ek7xTFx8R8juSwYABRcLRPR6C7LFvA5iG7jjyGx4hzQsnkyV7hzwKBghnah0TSaTxMA8qCY%2FhTcYv8DlLG8EPGvW9ucYCT%2BafoRIVg%3D%3D: HTTPSConnectionPool(host='storage.googleapis.com', port=443): Max retries exceeded with url: /wandb-production.appspot.com/leobaro/datacomp/1ql4ettk/config.yaml?Expires=1735068918&GoogleAccessId=gorilla-files-url-signer-man%40wandb-production.iam.gserviceaccount.com&Signature=FGSC4lGNweshlGOVlc%2BJ5L8jwCN%2B2sDS3UGnMovoMoDPNXZKBQC4DqsitbxzXskQCxw31OBjuhqi%2BA63JYCgQcQAyDWT9aPmXSD26Z1Mj%2FY3E9qP%2FvtBi7D4A7PCR9tOWsbIJbZO4p44gi%2BKbes38dZcs9WXQGjKE7ZtiGc%2FfViWD1ycg4aIJqbmeb%2BlqfIFFRK7QmqkAT1QswiLO1FPtx9BLdGXKlhf9%2B2BquKpmTm5z031Ek7xTFx8R8juSwYABRcLRPR6C7LFvA5iG7jjyGx4hzQsnkyV7hzwKBghnah0TSaTxMA8qCY%2FhTcYv8DlLG8EPGvW9ucYCT%2BafoRIVg%3D%3D (Caused by NewConnectionError('<urllib3.connection.HTTPSConnection object at 0x707788584e80>: Failed to establish a new connection: [Errno -3] Temporary failure in name resolution'))
2024-12-23 20:37:50,338 ERROR   Thread-9  :42959 [internal_api.py:upload_file():1696] upload_file request headers: {'User-Agent': 'python-requests/2.28.1', 'Accept-Encoding': 'gzip, deflate', 'Accept': '*/*', 'Connection': 'keep-alive', 'Content-Length': '2105'}
2024-12-23 20:37:50,338 ERROR   Thread-9  :42959 [internal_api.py:upload_file():1698] upload_file response body: 
2024-12-23 20:38:47,831 ERROR   Thread-9  :42959 [internal_api.py:upload_file():1694] upload_file exception https://storage.googleapis.com/wandb-production.appspot.com/leobaro/datacomp/1ql4ettk/config.yaml?Expires=1735068918&GoogleAccessId=gorilla-files-url-signer-man%40wandb-production.iam.gserviceaccount.com&Signature=FGSC4lGNweshlGOVlc%2BJ5L8jwCN%2B2sDS3UGnMovoMoDPNXZKBQC4DqsitbxzXskQCxw31OBjuhqi%2BA63JYCgQcQAyDWT9aPmXSD26Z1Mj%2FY3E9qP%2FvtBi7D4A7PCR9tOWsbIJbZO4p44gi%2BKbes38dZcs9WXQGjKE7ZtiGc%2FfViWD1ycg4aIJqbmeb%2BlqfIFFRK7QmqkAT1QswiLO1FPtx9BLdGXKlhf9%2B2BquKpmTm5z031Ek7xTFx8R8juSwYABRcLRPR6C7LFvA5iG7jjyGx4hzQsnkyV7hzwKBghnah0TSaTxMA8qCY%2FhTcYv8DlLG8EPGvW9ucYCT%2BafoRIVg%3D%3D: HTTPSConnectionPool(host='storage.googleapis.com', port=443): Max retries exceeded with url: /wandb-production.appspot.com/leobaro/datacomp/1ql4ettk/config.yaml?Expires=1735068918&GoogleAccessId=gorilla-files-url-signer-man%40wandb-production.iam.gserviceaccount.com&Signature=FGSC4lGNweshlGOVlc%2BJ5L8jwCN%2B2sDS3UGnMovoMoDPNXZKBQC4DqsitbxzXskQCxw31OBjuhqi%2BA63JYCgQcQAyDWT9aPmXSD26Z1Mj%2FY3E9qP%2FvtBi7D4A7PCR9tOWsbIJbZO4p44gi%2BKbes38dZcs9WXQGjKE7ZtiGc%2FfViWD1ycg4aIJqbmeb%2BlqfIFFRK7QmqkAT1QswiLO1FPtx9BLdGXKlhf9%2B2BquKpmTm5z031Ek7xTFx8R8juSwYABRcLRPR6C7LFvA5iG7jjyGx4hzQsnkyV7hzwKBghnah0TSaTxMA8qCY%2FhTcYv8DlLG8EPGvW9ucYCT%2BafoRIVg%3D%3D (Caused by NewConnectionError('<urllib3.connection.HTTPSConnection object at 0x707788584070>: Failed to establish a new connection: [Errno -3] Temporary failure in name resolution'))
2024-12-23 20:38:47,831 ERROR   Thread-9  :42959 [internal_api.py:upload_file():1696] upload_file request headers: {'User-Agent': 'python-requests/2.28.1', 'Accept-Encoding': 'gzip, deflate', 'Accept': '*/*', 'Connection': 'keep-alive', 'Content-Length': '2105'}
2024-12-23 20:38:47,831 ERROR   Thread-9  :42959 [internal_api.py:upload_file():1698] upload_file response body: 
2024-12-23 20:40:21,897 ERROR   Thread-9  :42959 [internal_api.py:upload_file():1694] upload_file exception https://storage.googleapis.com/wandb-production.appspot.com/leobaro/datacomp/1ql4ettk/config.yaml?Expires=1735068918&GoogleAccessId=gorilla-files-url-signer-man%40wandb-production.iam.gserviceaccount.com&Signature=FGSC4lGNweshlGOVlc%2BJ5L8jwCN%2B2sDS3UGnMovoMoDPNXZKBQC4DqsitbxzXskQCxw31OBjuhqi%2BA63JYCgQcQAyDWT9aPmXSD26Z1Mj%2FY3E9qP%2FvtBi7D4A7PCR9tOWsbIJbZO4p44gi%2BKbes38dZcs9WXQGjKE7ZtiGc%2FfViWD1ycg4aIJqbmeb%2BlqfIFFRK7QmqkAT1QswiLO1FPtx9BLdGXKlhf9%2B2BquKpmTm5z031Ek7xTFx8R8juSwYABRcLRPR6C7LFvA5iG7jjyGx4hzQsnkyV7hzwKBghnah0TSaTxMA8qCY%2FhTcYv8DlLG8EPGvW9ucYCT%2BafoRIVg%3D%3D: HTTPSConnectionPool(host='storage.googleapis.com', port=443): Max retries exceeded with url: /wandb-production.appspot.com/leobaro/datacomp/1ql4ettk/config.yaml?Expires=1735068918&GoogleAccessId=gorilla-files-url-signer-man%40wandb-production.iam.gserviceaccount.com&Signature=FGSC4lGNweshlGOVlc%2BJ5L8jwCN%2B2sDS3UGnMovoMoDPNXZKBQC4DqsitbxzXskQCxw31OBjuhqi%2BA63JYCgQcQAyDWT9aPmXSD26Z1Mj%2FY3E9qP%2FvtBi7D4A7PCR9tOWsbIJbZO4p44gi%2BKbes38dZcs9WXQGjKE7ZtiGc%2FfViWD1ycg4aIJqbmeb%2BlqfIFFRK7QmqkAT1QswiLO1FPtx9BLdGXKlhf9%2B2BquKpmTm5z031Ek7xTFx8R8juSwYABRcLRPR6C7LFvA5iG7jjyGx4hzQsnkyV7hzwKBghnah0TSaTxMA8qCY%2FhTcYv8DlLG8EPGvW9ucYCT%2BafoRIVg%3D%3D (Caused by NewConnectionError('<urllib3.connection.HTTPSConnection object at 0x7077885842e0>: Failed to establish a new connection: [Errno 111] Connection refused'))
2024-12-23 20:40:21,897 ERROR   Thread-9  :42959 [internal_api.py:upload_file():1696] upload_file request headers: {'User-Agent': 'python-requests/2.28.1', 'Accept-Encoding': 'gzip, deflate', 'Accept': '*/*', 'Connection': 'keep-alive', 'Content-Length': '2105'}
2024-12-23 20:40:21,897 ERROR   Thread-9  :42959 [internal_api.py:upload_file():1698] upload_file response body: 
2024-12-23 20:40:53,894 WARNING FileStreamThread:42959 [file_stream.py:request_with_retry():589] requests_with_retry encountered retryable exception: HTTPSConnectionPool(host='api.wandb.ai', port=443): Max retries exceeded with url: /files/leobaro/datacomp/1ql4ettk/file_stream (Caused by NewConnectionError('<urllib3.connection.HTTPSConnection object at 0x707788584ee0>: Failed to establish a new connection: [Errno 111] Connection refused')). func: <bound method Session.post of <requests.sessions.Session object at 0x70778cf07c40>>, args: ('https://api.wandb.ai/files/leobaro/datacomp/1ql4ettk/file_stream',), kwargs: {'json': {'complete': False, 'failed': False, 'dropped': 0, 'uploaded': []}}
2024-12-23 20:43:08,205 ERROR   Thread-9  :42959 [internal_api.py:upload_file():1694] upload_file exception https://storage.googleapis.com/wandb-production.appspot.com/leobaro/datacomp/1ql4ettk/config.yaml?Expires=1735068918&GoogleAccessId=gorilla-files-url-signer-man%40wandb-production.iam.gserviceaccount.com&Signature=FGSC4lGNweshlGOVlc%2BJ5L8jwCN%2B2sDS3UGnMovoMoDPNXZKBQC4DqsitbxzXskQCxw31OBjuhqi%2BA63JYCgQcQAyDWT9aPmXSD26Z1Mj%2FY3E9qP%2FvtBi7D4A7PCR9tOWsbIJbZO4p44gi%2BKbes38dZcs9WXQGjKE7ZtiGc%2FfViWD1ycg4aIJqbmeb%2BlqfIFFRK7QmqkAT1QswiLO1FPtx9BLdGXKlhf9%2B2BquKpmTm5z031Ek7xTFx8R8juSwYABRcLRPR6C7LFvA5iG7jjyGx4hzQsnkyV7hzwKBghnah0TSaTxMA8qCY%2FhTcYv8DlLG8EPGvW9ucYCT%2BafoRIVg%3D%3D: HTTPSConnectionPool(host='storage.googleapis.com', port=443): Max retries exceeded with url: /wandb-production.appspot.com/leobaro/datacomp/1ql4ettk/config.yaml?Expires=1735068918&GoogleAccessId=gorilla-files-url-signer-man%40wandb-production.iam.gserviceaccount.com&Signature=FGSC4lGNweshlGOVlc%2BJ5L8jwCN%2B2sDS3UGnMovoMoDPNXZKBQC4DqsitbxzXskQCxw31OBjuhqi%2BA63JYCgQcQAyDWT9aPmXSD26Z1Mj%2FY3E9qP%2FvtBi7D4A7PCR9tOWsbIJbZO4p44gi%2BKbes38dZcs9WXQGjKE7ZtiGc%2FfViWD1ycg4aIJqbmeb%2BlqfIFFRK7QmqkAT1QswiLO1FPtx9BLdGXKlhf9%2B2BquKpmTm5z031Ek7xTFx8R8juSwYABRcLRPR6C7LFvA5iG7jjyGx4hzQsnkyV7hzwKBghnah0TSaTxMA8qCY%2FhTcYv8DlLG8EPGvW9ucYCT%2BafoRIVg%3D%3D (Caused by NewConnectionError('<urllib3.connection.HTTPSConnection object at 0x7077885857e0>: Failed to establish a new connection: [Errno -3] Temporary failure in name resolution'))
2024-12-23 20:43:08,205 ERROR   Thread-9  :42959 [internal_api.py:upload_file():1696] upload_file request headers: {'User-Agent': 'python-requests/2.28.1', 'Accept-Encoding': 'gzip, deflate', 'Accept': '*/*', 'Connection': 'keep-alive', 'Content-Length': '2105'}
2024-12-23 20:43:08,205 ERROR   Thread-9  :42959 [internal_api.py:upload_file():1698] upload_file response body: 
2024-12-23 20:46:16,395 WARNING FileStreamThread:42959 [file_stream.py:request_with_retry():589] requests_with_retry encountered retryable exception: HTTPSConnectionPool(host='api.wandb.ai', port=443): Max retries exceeded with url: /files/leobaro/datacomp/1ql4ettk/file_stream (Caused by NewConnectionError('<urllib3.connection.HTTPSConnection object at 0x707788585e70>: Failed to establish a new connection: [Errno 111] Connection refused')). func: <bound method Session.post of <requests.sessions.Session object at 0x70778cf07c40>>, args: ('https://api.wandb.ai/files/leobaro/datacomp/1ql4ettk/file_stream',), kwargs: {'json': {'complete': False, 'failed': False, 'dropped': 0, 'uploaded': []}}
2024-12-23 20:47:52,577 ERROR   Thread-9  :42959 [internal_api.py:upload_file():1694] upload_file exception https://storage.googleapis.com/wandb-production.appspot.com/leobaro/datacomp/1ql4ettk/config.yaml?Expires=1735068918&GoogleAccessId=gorilla-files-url-signer-man%40wandb-production.iam.gserviceaccount.com&Signature=FGSC4lGNweshlGOVlc%2BJ5L8jwCN%2B2sDS3UGnMovoMoDPNXZKBQC4DqsitbxzXskQCxw31OBjuhqi%2BA63JYCgQcQAyDWT9aPmXSD26Z1Mj%2FY3E9qP%2FvtBi7D4A7PCR9tOWsbIJbZO4p44gi%2BKbes38dZcs9WXQGjKE7ZtiGc%2FfViWD1ycg4aIJqbmeb%2BlqfIFFRK7QmqkAT1QswiLO1FPtx9BLdGXKlhf9%2B2BquKpmTm5z031Ek7xTFx8R8juSwYABRcLRPR6C7LFvA5iG7jjyGx4hzQsnkyV7hzwKBghnah0TSaTxMA8qCY%2FhTcYv8DlLG8EPGvW9ucYCT%2BafoRIVg%3D%3D: HTTPSConnectionPool(host='storage.googleapis.com', port=443): Max retries exceeded with url: /wandb-production.appspot.com/leobaro/datacomp/1ql4ettk/config.yaml?Expires=1735068918&GoogleAccessId=gorilla-files-url-signer-man%40wandb-production.iam.gserviceaccount.com&Signature=FGSC4lGNweshlGOVlc%2BJ5L8jwCN%2B2sDS3UGnMovoMoDPNXZKBQC4DqsitbxzXskQCxw31OBjuhqi%2BA63JYCgQcQAyDWT9aPmXSD26Z1Mj%2FY3E9qP%2FvtBi7D4A7PCR9tOWsbIJbZO4p44gi%2BKbes38dZcs9WXQGjKE7ZtiGc%2FfViWD1ycg4aIJqbmeb%2BlqfIFFRK7QmqkAT1QswiLO1FPtx9BLdGXKlhf9%2B2BquKpmTm5z031Ek7xTFx8R8juSwYABRcLRPR6C7LFvA5iG7jjyGx4hzQsnkyV7hzwKBghnah0TSaTxMA8qCY%2FhTcYv8DlLG8EPGvW9ucYCT%2BafoRIVg%3D%3D (Caused by NewConnectionError('<urllib3.connection.HTTPSConnection object at 0x707788585720>: Failed to establish a new connection: [Errno -3] Temporary failure in name resolution'))
2024-12-23 20:47:52,577 ERROR   Thread-9  :42959 [internal_api.py:upload_file():1696] upload_file request headers: {'User-Agent': 'python-requests/2.28.1', 'Accept-Encoding': 'gzip, deflate', 'Accept': '*/*', 'Connection': 'keep-alive', 'Content-Length': '2105'}
2024-12-23 20:47:52,577 ERROR   Thread-9  :42959 [internal_api.py:upload_file():1698] upload_file response body: 
2024-12-23 20:53:33,193 ERROR   Thread-9  :42959 [internal_api.py:upload_file():1694] upload_file exception https://storage.googleapis.com/wandb-production.appspot.com/leobaro/datacomp/1ql4ettk/config.yaml?Expires=1735068918&GoogleAccessId=gorilla-files-url-signer-man%40wandb-production.iam.gserviceaccount.com&Signature=FGSC4lGNweshlGOVlc%2BJ5L8jwCN%2B2sDS3UGnMovoMoDPNXZKBQC4DqsitbxzXskQCxw31OBjuhqi%2BA63JYCgQcQAyDWT9aPmXSD26Z1Mj%2FY3E9qP%2FvtBi7D4A7PCR9tOWsbIJbZO4p44gi%2BKbes38dZcs9WXQGjKE7ZtiGc%2FfViWD1ycg4aIJqbmeb%2BlqfIFFRK7QmqkAT1QswiLO1FPtx9BLdGXKlhf9%2B2BquKpmTm5z031Ek7xTFx8R8juSwYABRcLRPR6C7LFvA5iG7jjyGx4hzQsnkyV7hzwKBghnah0TSaTxMA8qCY%2FhTcYv8DlLG8EPGvW9ucYCT%2BafoRIVg%3D%3D: HTTPSConnectionPool(host='storage.googleapis.com', port=443): Max retries exceeded with url: /wandb-production.appspot.com/leobaro/datacomp/1ql4ettk/config.yaml?Expires=1735068918&GoogleAccessId=gorilla-files-url-signer-man%40wandb-production.iam.gserviceaccount.com&Signature=FGSC4lGNweshlGOVlc%2BJ5L8jwCN%2B2sDS3UGnMovoMoDPNXZKBQC4DqsitbxzXskQCxw31OBjuhqi%2BA63JYCgQcQAyDWT9aPmXSD26Z1Mj%2FY3E9qP%2FvtBi7D4A7PCR9tOWsbIJbZO4p44gi%2BKbes38dZcs9WXQGjKE7ZtiGc%2FfViWD1ycg4aIJqbmeb%2BlqfIFFRK7QmqkAT1QswiLO1FPtx9BLdGXKlhf9%2B2BquKpmTm5z031Ek7xTFx8R8juSwYABRcLRPR6C7LFvA5iG7jjyGx4hzQsnkyV7hzwKBghnah0TSaTxMA8qCY%2FhTcYv8DlLG8EPGvW9ucYCT%2BafoRIVg%3D%3D (Caused by NewConnectionError('<urllib3.connection.HTTPSConnection object at 0x7077885848e0>: Failed to establish a new connection: [Errno -3] Temporary failure in name resolution'))
2024-12-23 20:53:33,193 ERROR   Thread-9  :42959 [internal_api.py:upload_file():1696] upload_file request headers: {'User-Agent': 'python-requests/2.28.1', 'Accept-Encoding': 'gzip, deflate', 'Accept': '*/*', 'Connection': 'keep-alive', 'Content-Length': '2105'}
2024-12-23 20:53:33,193 ERROR   Thread-9  :42959 [internal_api.py:upload_file():1698] upload_file response body: 
2024-12-23 20:59:04,424 ERROR   Thread-9  :42959 [internal_api.py:upload_file():1694] upload_file exception https://storage.googleapis.com/wandb-production.appspot.com/leobaro/datacomp/1ql4ettk/config.yaml?Expires=1735068918&GoogleAccessId=gorilla-files-url-signer-man%40wandb-production.iam.gserviceaccount.com&Signature=FGSC4lGNweshlGOVlc%2BJ5L8jwCN%2B2sDS3UGnMovoMoDPNXZKBQC4DqsitbxzXskQCxw31OBjuhqi%2BA63JYCgQcQAyDWT9aPmXSD26Z1Mj%2FY3E9qP%2FvtBi7D4A7PCR9tOWsbIJbZO4p44gi%2BKbes38dZcs9WXQGjKE7ZtiGc%2FfViWD1ycg4aIJqbmeb%2BlqfIFFRK7QmqkAT1QswiLO1FPtx9BLdGXKlhf9%2B2BquKpmTm5z031Ek7xTFx8R8juSwYABRcLRPR6C7LFvA5iG7jjyGx4hzQsnkyV7hzwKBghnah0TSaTxMA8qCY%2FhTcYv8DlLG8EPGvW9ucYCT%2BafoRIVg%3D%3D: HTTPSConnectionPool(host='storage.googleapis.com', port=443): Max retries exceeded with url: /wandb-production.appspot.com/leobaro/datacomp/1ql4ettk/config.yaml?Expires=1735068918&GoogleAccessId=gorilla-files-url-signer-man%40wandb-production.iam.gserviceaccount.com&Signature=FGSC4lGNweshlGOVlc%2BJ5L8jwCN%2B2sDS3UGnMovoMoDPNXZKBQC4DqsitbxzXskQCxw31OBjuhqi%2BA63JYCgQcQAyDWT9aPmXSD26Z1Mj%2FY3E9qP%2FvtBi7D4A7PCR9tOWsbIJbZO4p44gi%2BKbes38dZcs9WXQGjKE7ZtiGc%2FfViWD1ycg4aIJqbmeb%2BlqfIFFRK7QmqkAT1QswiLO1FPtx9BLdGXKlhf9%2B2BquKpmTm5z031Ek7xTFx8R8juSwYABRcLRPR6C7LFvA5iG7jjyGx4hzQsnkyV7hzwKBghnah0TSaTxMA8qCY%2FhTcYv8DlLG8EPGvW9ucYCT%2BafoRIVg%3D%3D (Caused by NewConnectionError('<urllib3.connection.HTTPSConnection object at 0x707788584c40>: Failed to establish a new connection: [Errno 111] Connection refused'))
2024-12-23 20:59:04,424 ERROR   Thread-9  :42959 [internal_api.py:upload_file():1696] upload_file request headers: {'User-Agent': 'python-requests/2.28.1', 'Accept-Encoding': 'gzip, deflate', 'Accept': '*/*', 'Connection': 'keep-alive', 'Content-Length': '2105'}
2024-12-23 20:59:04,424 ERROR   Thread-9  :42959 [internal_api.py:upload_file():1698] upload_file response body: 
2024-12-23 21:04:53,095 ERROR   Thread-9  :42959 [internal_api.py:upload_file():1694] upload_file exception https://storage.googleapis.com/wandb-production.appspot.com/leobaro/datacomp/1ql4ettk/config.yaml?Expires=1735068918&GoogleAccessId=gorilla-files-url-signer-man%40wandb-production.iam.gserviceaccount.com&Signature=FGSC4lGNweshlGOVlc%2BJ5L8jwCN%2B2sDS3UGnMovoMoDPNXZKBQC4DqsitbxzXskQCxw31OBjuhqi%2BA63JYCgQcQAyDWT9aPmXSD26Z1Mj%2FY3E9qP%2FvtBi7D4A7PCR9tOWsbIJbZO4p44gi%2BKbes38dZcs9WXQGjKE7ZtiGc%2FfViWD1ycg4aIJqbmeb%2BlqfIFFRK7QmqkAT1QswiLO1FPtx9BLdGXKlhf9%2B2BquKpmTm5z031Ek7xTFx8R8juSwYABRcLRPR6C7LFvA5iG7jjyGx4hzQsnkyV7hzwKBghnah0TSaTxMA8qCY%2FhTcYv8DlLG8EPGvW9ucYCT%2BafoRIVg%3D%3D: HTTPSConnectionPool(host='storage.googleapis.com', port=443): Max retries exceeded with url: /wandb-production.appspot.com/leobaro/datacomp/1ql4ettk/config.yaml?Expires=1735068918&GoogleAccessId=gorilla-files-url-signer-man%40wandb-production.iam.gserviceaccount.com&Signature=FGSC4lGNweshlGOVlc%2BJ5L8jwCN%2B2sDS3UGnMovoMoDPNXZKBQC4DqsitbxzXskQCxw31OBjuhqi%2BA63JYCgQcQAyDWT9aPmXSD26Z1Mj%2FY3E9qP%2FvtBi7D4A7PCR9tOWsbIJbZO4p44gi%2BKbes38dZcs9WXQGjKE7ZtiGc%2FfViWD1ycg4aIJqbmeb%2BlqfIFFRK7QmqkAT1QswiLO1FPtx9BLdGXKlhf9%2B2BquKpmTm5z031Ek7xTFx8R8juSwYABRcLRPR6C7LFvA5iG7jjyGx4hzQsnkyV7hzwKBghnah0TSaTxMA8qCY%2FhTcYv8DlLG8EPGvW9ucYCT%2BafoRIVg%3D%3D (Caused by NewConnectionError('<urllib3.connection.HTTPSConnection object at 0x7077885867d0>: Failed to establish a new connection: [Errno 111] Connection refused'))
2024-12-23 21:04:53,095 ERROR   Thread-9  :42959 [internal_api.py:upload_file():1696] upload_file request headers: {'User-Agent': 'python-requests/2.28.1', 'Accept-Encoding': 'gzip, deflate', 'Accept': '*/*', 'Connection': 'keep-alive', 'Content-Length': '2105'}
2024-12-23 21:04:53,095 ERROR   Thread-9  :42959 [internal_api.py:upload_file():1698] upload_file response body: 
2024-12-23 21:11:11,641 ERROR   Thread-9  :42959 [internal_api.py:upload_file():1694] upload_file exception https://storage.googleapis.com/wandb-production.appspot.com/leobaro/datacomp/1ql4ettk/config.yaml?Expires=1735068918&GoogleAccessId=gorilla-files-url-signer-man%40wandb-production.iam.gserviceaccount.com&Signature=FGSC4lGNweshlGOVlc%2BJ5L8jwCN%2B2sDS3UGnMovoMoDPNXZKBQC4DqsitbxzXskQCxw31OBjuhqi%2BA63JYCgQcQAyDWT9aPmXSD26Z1Mj%2FY3E9qP%2FvtBi7D4A7PCR9tOWsbIJbZO4p44gi%2BKbes38dZcs9WXQGjKE7ZtiGc%2FfViWD1ycg4aIJqbmeb%2BlqfIFFRK7QmqkAT1QswiLO1FPtx9BLdGXKlhf9%2B2BquKpmTm5z031Ek7xTFx8R8juSwYABRcLRPR6C7LFvA5iG7jjyGx4hzQsnkyV7hzwKBghnah0TSaTxMA8qCY%2FhTcYv8DlLG8EPGvW9ucYCT%2BafoRIVg%3D%3D: HTTPSConnectionPool(host='storage.googleapis.com', port=443): Max retries exceeded with url: /wandb-production.appspot.com/leobaro/datacomp/1ql4ettk/config.yaml?Expires=1735068918&GoogleAccessId=gorilla-files-url-signer-man%40wandb-production.iam.gserviceaccount.com&Signature=FGSC4lGNweshlGOVlc%2BJ5L8jwCN%2B2sDS3UGnMovoMoDPNXZKBQC4DqsitbxzXskQCxw31OBjuhqi%2BA63JYCgQcQAyDWT9aPmXSD26Z1Mj%2FY3E9qP%2FvtBi7D4A7PCR9tOWsbIJbZO4p44gi%2BKbes38dZcs9WXQGjKE7ZtiGc%2FfViWD1ycg4aIJqbmeb%2BlqfIFFRK7QmqkAT1QswiLO1FPtx9BLdGXKlhf9%2B2BquKpmTm5z031Ek7xTFx8R8juSwYABRcLRPR6C7LFvA5iG7jjyGx4hzQsnkyV7hzwKBghnah0TSaTxMA8qCY%2FhTcYv8DlLG8EPGvW9ucYCT%2BafoRIVg%3D%3D (Caused by NewConnectionError('<urllib3.connection.HTTPSConnection object at 0x70778855b400>: Failed to establish a new connection: [Errno 111] Connection refused'))
2024-12-23 21:11:11,641 ERROR   Thread-9  :42959 [internal_api.py:upload_file():1696] upload_file request headers: {'User-Agent': 'python-requests/2.28.1', 'Accept-Encoding': 'gzip, deflate', 'Accept': '*/*', 'Connection': 'keep-alive', 'Content-Length': '2105'}
2024-12-23 21:11:11,641 ERROR   Thread-9  :42959 [internal_api.py:upload_file():1698] upload_file response body: 
2024-12-23 21:17:22,428 ERROR   Thread-9  :42959 [internal_api.py:upload_file():1694] upload_file exception https://storage.googleapis.com/wandb-production.appspot.com/leobaro/datacomp/1ql4ettk/config.yaml?Expires=1735068918&GoogleAccessId=gorilla-files-url-signer-man%40wandb-production.iam.gserviceaccount.com&Signature=FGSC4lGNweshlGOVlc%2BJ5L8jwCN%2B2sDS3UGnMovoMoDPNXZKBQC4DqsitbxzXskQCxw31OBjuhqi%2BA63JYCgQcQAyDWT9aPmXSD26Z1Mj%2FY3E9qP%2FvtBi7D4A7PCR9tOWsbIJbZO4p44gi%2BKbes38dZcs9WXQGjKE7ZtiGc%2FfViWD1ycg4aIJqbmeb%2BlqfIFFRK7QmqkAT1QswiLO1FPtx9BLdGXKlhf9%2B2BquKpmTm5z031Ek7xTFx8R8juSwYABRcLRPR6C7LFvA5iG7jjyGx4hzQsnkyV7hzwKBghnah0TSaTxMA8qCY%2FhTcYv8DlLG8EPGvW9ucYCT%2BafoRIVg%3D%3D: HTTPSConnectionPool(host='storage.googleapis.com', port=443): Max retries exceeded with url: /wandb-production.appspot.com/leobaro/datacomp/1ql4ettk/config.yaml?Expires=1735068918&GoogleAccessId=gorilla-files-url-signer-man%40wandb-production.iam.gserviceaccount.com&Signature=FGSC4lGNweshlGOVlc%2BJ5L8jwCN%2B2sDS3UGnMovoMoDPNXZKBQC4DqsitbxzXskQCxw31OBjuhqi%2BA63JYCgQcQAyDWT9aPmXSD26Z1Mj%2FY3E9qP%2FvtBi7D4A7PCR9tOWsbIJbZO4p44gi%2BKbes38dZcs9WXQGjKE7ZtiGc%2FfViWD1ycg4aIJqbmeb%2BlqfIFFRK7QmqkAT1QswiLO1FPtx9BLdGXKlhf9%2B2BquKpmTm5z031Ek7xTFx8R8juSwYABRcLRPR6C7LFvA5iG7jjyGx4hzQsnkyV7hzwKBghnah0TSaTxMA8qCY%2FhTcYv8DlLG8EPGvW9ucYCT%2BafoRIVg%3D%3D (Caused by NewConnectionError('<urllib3.connection.HTTPSConnection object at 0x707788586890>: Failed to establish a new connection: [Errno -3] Temporary failure in name resolution'))
2024-12-23 21:17:22,428 ERROR   Thread-9  :42959 [internal_api.py:upload_file():1696] upload_file request headers: {'User-Agent': 'python-requests/2.28.1', 'Accept-Encoding': 'gzip, deflate', 'Accept': '*/*', 'Connection': 'keep-alive', 'Content-Length': '2105'}
2024-12-23 21:17:22,428 ERROR   Thread-9  :42959 [internal_api.py:upload_file():1698] upload_file response body: 
2024-12-23 21:23:17,897 ERROR   Thread-9  :42959 [internal_api.py:upload_file():1694] upload_file exception https://storage.googleapis.com/wandb-production.appspot.com/leobaro/datacomp/1ql4ettk/config.yaml?Expires=1735068918&GoogleAccessId=gorilla-files-url-signer-man%40wandb-production.iam.gserviceaccount.com&Signature=FGSC4lGNweshlGOVlc%2BJ5L8jwCN%2B2sDS3UGnMovoMoDPNXZKBQC4DqsitbxzXskQCxw31OBjuhqi%2BA63JYCgQcQAyDWT9aPmXSD26Z1Mj%2FY3E9qP%2FvtBi7D4A7PCR9tOWsbIJbZO4p44gi%2BKbes38dZcs9WXQGjKE7ZtiGc%2FfViWD1ycg4aIJqbmeb%2BlqfIFFRK7QmqkAT1QswiLO1FPtx9BLdGXKlhf9%2B2BquKpmTm5z031Ek7xTFx8R8juSwYABRcLRPR6C7LFvA5iG7jjyGx4hzQsnkyV7hzwKBghnah0TSaTxMA8qCY%2FhTcYv8DlLG8EPGvW9ucYCT%2BafoRIVg%3D%3D: HTTPSConnectionPool(host='storage.googleapis.com', port=443): Max retries exceeded with url: /wandb-production.appspot.com/leobaro/datacomp/1ql4ettk/config.yaml?Expires=1735068918&GoogleAccessId=gorilla-files-url-signer-man%40wandb-production.iam.gserviceaccount.com&Signature=FGSC4lGNweshlGOVlc%2BJ5L8jwCN%2B2sDS3UGnMovoMoDPNXZKBQC4DqsitbxzXskQCxw31OBjuhqi%2BA63JYCgQcQAyDWT9aPmXSD26Z1Mj%2FY3E9qP%2FvtBi7D4A7PCR9tOWsbIJbZO4p44gi%2BKbes38dZcs9WXQGjKE7ZtiGc%2FfViWD1ycg4aIJqbmeb%2BlqfIFFRK7QmqkAT1QswiLO1FPtx9BLdGXKlhf9%2B2BquKpmTm5z031Ek7xTFx8R8juSwYABRcLRPR6C7LFvA5iG7jjyGx4hzQsnkyV7hzwKBghnah0TSaTxMA8qCY%2FhTcYv8DlLG8EPGvW9ucYCT%2BafoRIVg%3D%3D (Caused by NewConnectionError('<urllib3.connection.HTTPSConnection object at 0x707788584b80>: Failed to establish a new connection: [Errno 111] Connection refused'))
2024-12-23 21:23:17,897 ERROR   Thread-9  :42959 [internal_api.py:upload_file():1696] upload_file request headers: {'User-Agent': 'python-requests/2.28.1', 'Accept-Encoding': 'gzip, deflate', 'Accept': '*/*', 'Connection': 'keep-alive', 'Content-Length': '2105'}
2024-12-23 21:23:17,897 ERROR   Thread-9  :42959 [internal_api.py:upload_file():1698] upload_file response body: 
2024-12-23 21:29:11,513 ERROR   Thread-9  :42959 [internal_api.py:upload_file():1694] upload_file exception https://storage.googleapis.com/wandb-production.appspot.com/leobaro/datacomp/1ql4ettk/config.yaml?Expires=1735068918&GoogleAccessId=gorilla-files-url-signer-man%40wandb-production.iam.gserviceaccount.com&Signature=FGSC4lGNweshlGOVlc%2BJ5L8jwCN%2B2sDS3UGnMovoMoDPNXZKBQC4DqsitbxzXskQCxw31OBjuhqi%2BA63JYCgQcQAyDWT9aPmXSD26Z1Mj%2FY3E9qP%2FvtBi7D4A7PCR9tOWsbIJbZO4p44gi%2BKbes38dZcs9WXQGjKE7ZtiGc%2FfViWD1ycg4aIJqbmeb%2BlqfIFFRK7QmqkAT1QswiLO1FPtx9BLdGXKlhf9%2B2BquKpmTm5z031Ek7xTFx8R8juSwYABRcLRPR6C7LFvA5iG7jjyGx4hzQsnkyV7hzwKBghnah0TSaTxMA8qCY%2FhTcYv8DlLG8EPGvW9ucYCT%2BafoRIVg%3D%3D: HTTPSConnectionPool(host='storage.googleapis.com', port=443): Max retries exceeded with url: /wandb-production.appspot.com/leobaro/datacomp/1ql4ettk/config.yaml?Expires=1735068918&GoogleAccessId=gorilla-files-url-signer-man%40wandb-production.iam.gserviceaccount.com&Signature=FGSC4lGNweshlGOVlc%2BJ5L8jwCN%2B2sDS3UGnMovoMoDPNXZKBQC4DqsitbxzXskQCxw31OBjuhqi%2BA63JYCgQcQAyDWT9aPmXSD26Z1Mj%2FY3E9qP%2FvtBi7D4A7PCR9tOWsbIJbZO4p44gi%2BKbes38dZcs9WXQGjKE7ZtiGc%2FfViWD1ycg4aIJqbmeb%2BlqfIFFRK7QmqkAT1QswiLO1FPtx9BLdGXKlhf9%2B2BquKpmTm5z031Ek7xTFx8R8juSwYABRcLRPR6C7LFvA5iG7jjyGx4hzQsnkyV7hzwKBghnah0TSaTxMA8qCY%2FhTcYv8DlLG8EPGvW9ucYCT%2BafoRIVg%3D%3D (Caused by NewConnectionError('<urllib3.connection.HTTPSConnection object at 0x7077885852a0>: Failed to establish a new connection: [Errno 111] Connection refused'))
2024-12-23 21:29:11,513 ERROR   Thread-9  :42959 [internal_api.py:upload_file():1696] upload_file request headers: {'User-Agent': 'python-requests/2.28.1', 'Accept-Encoding': 'gzip, deflate', 'Accept': '*/*', 'Connection': 'keep-alive', 'Content-Length': '2105'}
2024-12-23 21:29:11,513 ERROR   Thread-9  :42959 [internal_api.py:upload_file():1698] upload_file response body: 
2024-12-23 21:35:27,020 ERROR   Thread-9  :42959 [internal_api.py:upload_file():1694] upload_file exception https://storage.googleapis.com/wandb-production.appspot.com/leobaro/datacomp/1ql4ettk/config.yaml?Expires=1735068918&GoogleAccessId=gorilla-files-url-signer-man%40wandb-production.iam.gserviceaccount.com&Signature=FGSC4lGNweshlGOVlc%2BJ5L8jwCN%2B2sDS3UGnMovoMoDPNXZKBQC4DqsitbxzXskQCxw31OBjuhqi%2BA63JYCgQcQAyDWT9aPmXSD26Z1Mj%2FY3E9qP%2FvtBi7D4A7PCR9tOWsbIJbZO4p44gi%2BKbes38dZcs9WXQGjKE7ZtiGc%2FfViWD1ycg4aIJqbmeb%2BlqfIFFRK7QmqkAT1QswiLO1FPtx9BLdGXKlhf9%2B2BquKpmTm5z031Ek7xTFx8R8juSwYABRcLRPR6C7LFvA5iG7jjyGx4hzQsnkyV7hzwKBghnah0TSaTxMA8qCY%2FhTcYv8DlLG8EPGvW9ucYCT%2BafoRIVg%3D%3D: HTTPSConnectionPool(host='storage.googleapis.com', port=443): Max retries exceeded with url: /wandb-production.appspot.com/leobaro/datacomp/1ql4ettk/config.yaml?Expires=1735068918&GoogleAccessId=gorilla-files-url-signer-man%40wandb-production.iam.gserviceaccount.com&Signature=FGSC4lGNweshlGOVlc%2BJ5L8jwCN%2B2sDS3UGnMovoMoDPNXZKBQC4DqsitbxzXskQCxw31OBjuhqi%2BA63JYCgQcQAyDWT9aPmXSD26Z1Mj%2FY3E9qP%2FvtBi7D4A7PCR9tOWsbIJbZO4p44gi%2BKbes38dZcs9WXQGjKE7ZtiGc%2FfViWD1ycg4aIJqbmeb%2BlqfIFFRK7QmqkAT1QswiLO1FPtx9BLdGXKlhf9%2B2BquKpmTm5z031Ek7xTFx8R8juSwYABRcLRPR6C7LFvA5iG7jjyGx4hzQsnkyV7hzwKBghnah0TSaTxMA8qCY%2FhTcYv8DlLG8EPGvW9ucYCT%2BafoRIVg%3D%3D (Caused by NewConnectionError('<urllib3.connection.HTTPSConnection object at 0x707788585d20>: Failed to establish a new connection: [Errno 111] Connection refused'))
2024-12-23 21:35:27,020 ERROR   Thread-9  :42959 [internal_api.py:upload_file():1696] upload_file request headers: {'User-Agent': 'python-requests/2.28.1', 'Accept-Encoding': 'gzip, deflate', 'Accept': '*/*', 'Connection': 'keep-alive', 'Content-Length': '2105'}
2024-12-23 21:35:27,020 ERROR   Thread-9  :42959 [internal_api.py:upload_file():1698] upload_file response body: 
2024-12-23 21:41:18,930 ERROR   Thread-9  :42959 [internal_api.py:upload_file():1694] upload_file exception https://storage.googleapis.com/wandb-production.appspot.com/leobaro/datacomp/1ql4ettk/config.yaml?Expires=1735068918&GoogleAccessId=gorilla-files-url-signer-man%40wandb-production.iam.gserviceaccount.com&Signature=FGSC4lGNweshlGOVlc%2BJ5L8jwCN%2B2sDS3UGnMovoMoDPNXZKBQC4DqsitbxzXskQCxw31OBjuhqi%2BA63JYCgQcQAyDWT9aPmXSD26Z1Mj%2FY3E9qP%2FvtBi7D4A7PCR9tOWsbIJbZO4p44gi%2BKbes38dZcs9WXQGjKE7ZtiGc%2FfViWD1ycg4aIJqbmeb%2BlqfIFFRK7QmqkAT1QswiLO1FPtx9BLdGXKlhf9%2B2BquKpmTm5z031Ek7xTFx8R8juSwYABRcLRPR6C7LFvA5iG7jjyGx4hzQsnkyV7hzwKBghnah0TSaTxMA8qCY%2FhTcYv8DlLG8EPGvW9ucYCT%2BafoRIVg%3D%3D: HTTPSConnectionPool(host='storage.googleapis.com', port=443): Max retries exceeded with url: /wandb-production.appspot.com/leobaro/datacomp/1ql4ettk/config.yaml?Expires=1735068918&GoogleAccessId=gorilla-files-url-signer-man%40wandb-production.iam.gserviceaccount.com&Signature=FGSC4lGNweshlGOVlc%2BJ5L8jwCN%2B2sDS3UGnMovoMoDPNXZKBQC4DqsitbxzXskQCxw31OBjuhqi%2BA63JYCgQcQAyDWT9aPmXSD26Z1Mj%2FY3E9qP%2FvtBi7D4A7PCR9tOWsbIJbZO4p44gi%2BKbes38dZcs9WXQGjKE7ZtiGc%2FfViWD1ycg4aIJqbmeb%2BlqfIFFRK7QmqkAT1QswiLO1FPtx9BLdGXKlhf9%2B2BquKpmTm5z031Ek7xTFx8R8juSwYABRcLRPR6C7LFvA5iG7jjyGx4hzQsnkyV7hzwKBghnah0TSaTxMA8qCY%2FhTcYv8DlLG8EPGvW9ucYCT%2BafoRIVg%3D%3D (Caused by NewConnectionError('<urllib3.connection.HTTPSConnection object at 0x707788584070>: Failed to establish a new connection: [Errno 111] Connection refused'))
2024-12-23 21:41:18,930 ERROR   Thread-9  :42959 [internal_api.py:upload_file():1696] upload_file request headers: {'User-Agent': 'python-requests/2.28.1', 'Accept-Encoding': 'gzip, deflate', 'Accept': '*/*', 'Connection': 'keep-alive', 'Content-Length': '2105'}
2024-12-23 21:41:18,930 ERROR   Thread-9  :42959 [internal_api.py:upload_file():1698] upload_file response body: 
2024-12-23 21:43:24,519 INFO    MainThread:42959 [internal.py:handle_exit():80] Internal process exited
