2024-12-23 20:24:16,970 INFO    MainThread:40885 [wandb_setup.py:_flush():76] Configure stats pid to 40885
2024-12-23 20:24:16,970 INFO    MainThread:40885 [wandb_setup.py:_flush():76] Loading settings from /home/leobaro/.config/wandb/settings
2024-12-23 20:24:16,970 INFO    MainThread:40885 [wandb_setup.py:_flush():76] Loading settings from /home/leobaro/workspace/labs/fair_spoke_8/fair_spoke_8_leonardo/scripts/wandb/settings
2024-12-23 20:24:16,970 INFO    MainThread:40885 [wandb_setup.py:_flush():76] Loading settings from environment variables: {}
2024-12-23 20:24:16,970 INFO    MainThread:40885 [wandb_setup.py:_flush():76] Inferring run settings from compute environment: {'program_relpath': 'fair_spoke_8_leonardo/scripts/download_upstream.py', 'program': '/home/leobaro/workspace/labs/fair_spoke_8/fair_spoke_8_leonardo/scripts/download_upstream.py'}
2024-12-23 20:24:16,970 INFO    MainThread:40885 [wandb_setup.py:_flush():76] Applying login settings: {'anonymous': 'allow'}
2024-12-23 20:24:16,970 INFO    MainThread:40885 [wandb_init.py:_log_setup():461] Logging user logs to /home/leobaro/workspace/labs/fair_spoke_8/fair_spoke_8_leonardo/scripts/wandb/run-20241223_202416-1ql4ettk/logs/debug.log
2024-12-23 20:24:16,970 INFO    MainThread:40885 [wandb_init.py:_log_setup():462] Logging internal logs to /home/leobaro/workspace/labs/fair_spoke_8/fair_spoke_8_leonardo/scripts/wandb/run-20241223_202416-1ql4ettk/logs/debug-internal.log
2024-12-23 20:24:16,970 INFO    MainThread:40885 [wandb_init.py:init():495] calling init triggers
2024-12-23 20:24:16,970 INFO    MainThread:40885 [wandb_init.py:init():498] wandb.init called with sweep_config: {}
config: {'url_list': '/home/leobaro/Downloads/datasets/web/datacomp/metadata', 'image_size': 512, 'output_folder': '/home/leobaro/Downloads/datasets/web/datacomp/shards', 'processes_count': 16, 'resize_mode': 'keep_ratio_largest', 'resize_only_if_bigger': True, 'upscale_interpolation': 'lanczos', 'downscale_interpolation': 'area', 'encode_quality': 95, 'encode_format': 'jpg', 'skip_reencode': False, 'output_format': 'webdataset', 'input_format': 'parquet', 'url_col': 'url', 'caption_col': 'text', 'bbox_col': 'face_bboxes', 'thread_count': 64, 'number_sample_per_shard': 10000, 'extract_exif': True, 'save_additional_columns': ['uid'], 'timeout': 10, 'enable_wandb': True, 'wandb_project': 'datacomp', 'oom_shard_count': 8, 'compute_hash': 'sha256', 'distributor': 'multiprocessing', 'subjob_size': 1000, 'retries': 3, 'disable_all_reencoding': False, 'min_image_size': 0, 'max_image_area': inf, 'max_aspect_ratio': inf, 'incremental_mode': 'incremental', 'max_shard_retry': 1, 'user_agent_token': None, 'disallowed_header_directives': ['noai', 'noimageai', 'noindex', 'noimageindex']}
2024-12-23 20:24:16,970 INFO    MainThread:40885 [wandb_init.py:init():548] starting backend
2024-12-23 20:24:16,971 INFO    MainThread:40885 [backend.py:_multiprocessing_setup():97] multiprocessing start_methods=fork,spawn,forkserver, using: spawn
2024-12-23 20:24:16,971 INFO    MainThread:40885 [backend.py:ensure_launched():217] starting backend process...
2024-12-23 20:24:16,973 INFO    MainThread:40885 [backend.py:ensure_launched():222] started backend process with pid: 42959
2024-12-23 20:24:16,973 INFO    MainThread:40885 [wandb_init.py:init():558] backend started and connected
2024-12-23 20:24:16,976 INFO    MainThread:40885 [wandb_init.py:init():634] updated telemetry
2024-12-23 20:24:16,980 INFO    MainThread:40885 [wandb_init.py:init():665] communicating run to backend with 30 second timeout
2024-12-23 20:24:46,980 INFO    MainThread:40885 [interface_shared.py:_communicate_run():326] couldn't get run from backend
2024-12-23 20:24:46,980 ERROR   MainThread:40885 [wandb_init.py:init():674] backend process timed out
2024-12-23 20:24:46,981 ERROR   MainThread:40885 [wandb_init.py:init():685] encountered error: Error communicating with wandb process
try: wandb.init(settings=wandb.Settings(start_method='fork'))
or:  wandb.init(settings=wandb.Settings(start_method='thread'))
For more info see: https://docs.wandb.ai/library/init#init-start-error
2024-12-23 20:25:15,637 ERROR   Thread-1 (wrapped_target):40885 [retry.py:__call__():132] Retry attempt failed:
Traceback (most recent call last):
  File "/home/leobaro/softwares/miniconda3/envs/datacomp/lib/python3.10/site-packages/urllib3/connection.py", line 174, in _new_conn
    conn = connection.create_connection(
  File "/home/leobaro/softwares/miniconda3/envs/datacomp/lib/python3.10/site-packages/urllib3/util/connection.py", line 72, in create_connection
    for res in socket.getaddrinfo(host, port, family, socket.SOCK_STREAM):
  File "/home/leobaro/softwares/miniconda3/envs/datacomp/lib/python3.10/socket.py", line 955, in getaddrinfo
    for res in _socket.getaddrinfo(host, port, family, type, proto, flags):
socket.gaierror: [Errno -3] Temporary failure in name resolution

During handling of the above exception, another exception occurred:

Traceback (most recent call last):
  File "/home/leobaro/softwares/miniconda3/envs/datacomp/lib/python3.10/site-packages/urllib3/connectionpool.py", line 703, in urlopen
    httplib_response = self._make_request(
  File "/home/leobaro/softwares/miniconda3/envs/datacomp/lib/python3.10/site-packages/urllib3/connectionpool.py", line 386, in _make_request
    self._validate_conn(conn)
  File "/home/leobaro/softwares/miniconda3/envs/datacomp/lib/python3.10/site-packages/urllib3/connectionpool.py", line 1042, in _validate_conn
    conn.connect()
  File "/home/leobaro/softwares/miniconda3/envs/datacomp/lib/python3.10/site-packages/urllib3/connection.py", line 358, in connect
    self.sock = conn = self._new_conn()
  File "/home/leobaro/softwares/miniconda3/envs/datacomp/lib/python3.10/site-packages/urllib3/connection.py", line 186, in _new_conn
    raise NewConnectionError(
urllib3.exceptions.NewConnectionError: <urllib3.connection.HTTPSConnection object at 0x7e4ccda7a5f0>: Failed to establish a new connection: [Errno -3] Temporary failure in name resolution

During handling of the above exception, another exception occurred:

Traceback (most recent call last):
  File "/home/leobaro/softwares/miniconda3/envs/datacomp/lib/python3.10/site-packages/requests/adapters.py", line 489, in send
    resp = conn.urlopen(
  File "/home/leobaro/softwares/miniconda3/envs/datacomp/lib/python3.10/site-packages/urllib3/connectionpool.py", line 787, in urlopen
    retries = retries.increment(
  File "/home/leobaro/softwares/miniconda3/envs/datacomp/lib/python3.10/site-packages/urllib3/util/retry.py", line 592, in increment
    raise MaxRetryError(_pool, url, error or ResponseError(cause))
urllib3.exceptions.MaxRetryError: HTTPSConnectionPool(host='api.wandb.ai', port=443): Max retries exceeded with url: /graphql (Caused by NewConnectionError('<urllib3.connection.HTTPSConnection object at 0x7e4ccda7a5f0>: Failed to establish a new connection: [Errno -3] Temporary failure in name resolution'))

During handling of the above exception, another exception occurred:

Traceback (most recent call last):
  File "/home/leobaro/softwares/miniconda3/envs/datacomp/lib/python3.10/site-packages/wandb/sdk/lib/retry.py", line 108, in __call__
    result = self._call_fn(*args, **kwargs)
  File "/home/leobaro/softwares/miniconda3/envs/datacomp/lib/python3.10/site-packages/wandb/sdk/internal/internal_api.py", line 158, in execute
    return self.client.execute(*args, **kwargs)
  File "/home/leobaro/softwares/miniconda3/envs/datacomp/lib/python3.10/site-packages/wandb/vendor/gql-0.2.0/wandb_gql/client.py", line 52, in execute
    result = self._get_result(document, *args, **kwargs)
  File "/home/leobaro/softwares/miniconda3/envs/datacomp/lib/python3.10/site-packages/wandb/vendor/gql-0.2.0/wandb_gql/client.py", line 60, in _get_result
    return self.transport.execute(document, *args, **kwargs)
  File "/home/leobaro/softwares/miniconda3/envs/datacomp/lib/python3.10/site-packages/wandb/vendor/gql-0.2.0/wandb_gql/transport/requests.py", line 38, in execute
    request = requests.post(self.url, **post_args)
  File "/home/leobaro/softwares/miniconda3/envs/datacomp/lib/python3.10/site-packages/requests/api.py", line 115, in post
    return request("post", url, data=data, json=json, **kwargs)
  File "/home/leobaro/softwares/miniconda3/envs/datacomp/lib/python3.10/site-packages/requests/api.py", line 59, in request
    return session.request(method=method, url=url, **kwargs)
  File "/home/leobaro/softwares/miniconda3/envs/datacomp/lib/python3.10/site-packages/requests/sessions.py", line 587, in request
    resp = self.send(prep, **send_kwargs)
  File "/home/leobaro/softwares/miniconda3/envs/datacomp/lib/python3.10/site-packages/requests/sessions.py", line 701, in send
    r = adapter.send(request, **kwargs)
  File "/home/leobaro/softwares/miniconda3/envs/datacomp/lib/python3.10/site-packages/requests/adapters.py", line 565, in send
    raise ConnectionError(e, request=request)
requests.exceptions.ConnectionError: HTTPSConnectionPool(host='api.wandb.ai', port=443): Max retries exceeded with url: /graphql (Caused by NewConnectionError('<urllib3.connection.HTTPSConnection object at 0x7e4ccda7a5f0>: Failed to establish a new connection: [Errno -3] Temporary failure in name resolution'))
2024-12-23 21:43:24,518 WARNING MainThread:40885 [wandb_init.py:init():1064] interrupted
Traceback (most recent call last):
  File "/home/leobaro/softwares/miniconda3/envs/datacomp/lib/python3.10/site-packages/wandb/sdk/wandb_init.py", line 1043, in init
    run = wi.init()
  File "/home/leobaro/softwares/miniconda3/envs/datacomp/lib/python3.10/site-packages/wandb/sdk/wandb_init.py", line 689, in init
    backend.cleanup()
  File "/home/leobaro/softwares/miniconda3/envs/datacomp/lib/python3.10/site-packages/wandb/sdk/backend/backend.py", line 248, in cleanup
    self.wandb_process.join()
  File "/home/leobaro/softwares/miniconda3/envs/datacomp/lib/python3.10/multiprocessing/process.py", line 149, in join
    res = self._popen.wait(timeout)
  File "/home/leobaro/softwares/miniconda3/envs/datacomp/lib/python3.10/multiprocessing/popen_fork.py", line 43, in wait
    return self.poll(os.WNOHANG if timeout == 0.0 else 0)
  File "/home/leobaro/softwares/miniconda3/envs/datacomp/lib/python3.10/multiprocessing/popen_fork.py", line 27, in poll
    pid, sts = os.waitpid(self.pid, flag)
KeyboardInterrupt
