2025-01-14 14:17:28,866 INFO    MainThread:31595 [internal.py:wandb_internal():90] W&B internal server running at pid: 31595, started at: 2025-01-14 14:17:28.866709
2025-01-14 14:17:28,869 INFO    WriterThread:31595 [datastore.py:open_for_write():75] open: /home/leobaro/workspace/labs/fair_spoke_8/fair_spoke_8_leonardo/datacomp_download/wandb/run-20250114_141728-2w6hucrj/run-2w6hucrj.wandb
2025-01-14 14:17:28,983 DEBUG   SenderThread:31595 [sender.py:send():236] send: header
2025-01-14 14:17:28,983 DEBUG   SenderThread:31595 [sender.py:send():236] send: run
2025-01-14 14:17:58,481 DEBUG   HandlerThread:31595 [handler.py:handle_request():140] handle_request: shutdown
2025-01-14 14:17:58,481 INFO    HandlerThread:31595 [handler.py:finish():806] shutting down handler
2025-01-14 14:17:58,874 INFO    WriterThread:31595 [datastore.py:close():279] close: /home/leobaro/workspace/labs/fair_spoke_8/fair_spoke_8_leonardo/datacomp_download/wandb/run-20250114_141728-2w6hucrj/run-2w6hucrj.wandb
2025-01-14 14:18:03,569 ERROR   SenderThread:31595 [retry.py:__call__():132] Retry attempt failed:
Traceback (most recent call last):
  File "/home/leobaro/softwares/miniconda3/envs/datacomp/lib/python3.10/site-packages/urllib3/connectionpool.py", line 703, in urlopen
    httplib_response = self._make_request(
  File "/home/leobaro/softwares/miniconda3/envs/datacomp/lib/python3.10/site-packages/urllib3/connectionpool.py", line 386, in _make_request
    self._validate_conn(conn)
  File "/home/leobaro/softwares/miniconda3/envs/datacomp/lib/python3.10/site-packages/urllib3/connectionpool.py", line 1042, in _validate_conn
    conn.connect()
  File "/home/leobaro/softwares/miniconda3/envs/datacomp/lib/python3.10/site-packages/urllib3/connection.py", line 414, in connect
    self.sock = ssl_wrap_socket(
  File "/home/leobaro/softwares/miniconda3/envs/datacomp/lib/python3.10/site-packages/urllib3/util/ssl_.py", line 449, in ssl_wrap_socket
    ssl_sock = _ssl_wrap_socket_impl(
  File "/home/leobaro/softwares/miniconda3/envs/datacomp/lib/python3.10/site-packages/urllib3/util/ssl_.py", line 493, in _ssl_wrap_socket_impl
    return ssl_context.wrap_socket(sock, server_hostname=server_hostname)
  File "/home/leobaro/softwares/miniconda3/envs/datacomp/lib/python3.10/ssl.py", line 513, in wrap_socket
    return self.sslsocket_class._create(
  File "/home/leobaro/softwares/miniconda3/envs/datacomp/lib/python3.10/ssl.py", line 1071, in _create
    self.do_handshake()
  File "/home/leobaro/softwares/miniconda3/envs/datacomp/lib/python3.10/ssl.py", line 1342, in do_handshake
    self._sslobj.do_handshake()
ssl.SSLEOFError: EOF occurred in violation of protocol (_ssl.c:997)

During handling of the above exception, another exception occurred:

Traceback (most recent call last):
  File "/home/leobaro/softwares/miniconda3/envs/datacomp/lib/python3.10/site-packages/requests/adapters.py", line 489, in send
    resp = conn.urlopen(
  File "/home/leobaro/softwares/miniconda3/envs/datacomp/lib/python3.10/site-packages/urllib3/connectionpool.py", line 787, in urlopen
    retries = retries.increment(
  File "/home/leobaro/softwares/miniconda3/envs/datacomp/lib/python3.10/site-packages/urllib3/util/retry.py", line 592, in increment
    raise MaxRetryError(_pool, url, error or ResponseError(cause))
urllib3.exceptions.MaxRetryError: HTTPSConnectionPool(host='api.wandb.ai', port=443): Max retries exceeded with url: /graphql (Caused by SSLError(SSLEOFError(8, 'EOF occurred in violation of protocol (_ssl.c:997)')))

During handling of the above exception, another exception occurred:

Traceback (most recent call last):
  File "/home/leobaro/softwares/miniconda3/envs/datacomp/lib/python3.10/site-packages/wandb/sdk/lib/retry.py", line 108, in __call__
    result = self._call_fn(*args, **kwargs)
  File "/home/leobaro/softwares/miniconda3/envs/datacomp/lib/python3.10/site-packages/wandb/sdk/internal/internal_api.py", line 158, in execute
    return self.client.execute(*args, **kwargs)
  File "/home/leobaro/softwares/miniconda3/envs/datacomp/lib/python3.10/site-packages/wandb/vendor/gql-0.2.0/wandb_gql/client.py", line 52, in execute
    result = self._get_result(document, *args, **kwargs)
  File "/home/leobaro/softwares/miniconda3/envs/datacomp/lib/python3.10/site-packages/wandb/vendor/gql-0.2.0/wandb_gql/client.py", line 60, in _get_result
    return self.transport.execute(document, *args, **kwargs)
  File "/home/leobaro/softwares/miniconda3/envs/datacomp/lib/python3.10/site-packages/wandb/vendor/gql-0.2.0/wandb_gql/transport/requests.py", line 38, in execute
    request = requests.post(self.url, **post_args)
  File "/home/leobaro/softwares/miniconda3/envs/datacomp/lib/python3.10/site-packages/requests/api.py", line 115, in post
    return request("post", url, data=data, json=json, **kwargs)
  File "/home/leobaro/softwares/miniconda3/envs/datacomp/lib/python3.10/site-packages/requests/api.py", line 59, in request
    return session.request(method=method, url=url, **kwargs)
  File "/home/leobaro/softwares/miniconda3/envs/datacomp/lib/python3.10/site-packages/requests/sessions.py", line 587, in request
    resp = self.send(prep, **send_kwargs)
  File "/home/leobaro/softwares/miniconda3/envs/datacomp/lib/python3.10/site-packages/requests/sessions.py", line 701, in send
    r = adapter.send(request, **kwargs)
  File "/home/leobaro/softwares/miniconda3/envs/datacomp/lib/python3.10/site-packages/requests/adapters.py", line 563, in send
    raise SSLError(e, request=request)
requests.exceptions.SSLError: HTTPSConnectionPool(host='api.wandb.ai', port=443): Max retries exceeded with url: /graphql (Caused by SSLError(SSLEOFError(8, 'EOF occurred in violation of protocol (_ssl.c:997)')))
2025-01-14 14:23:19,081 INFO    SenderThread:31595 [dir_watcher.py:__init__():216] watching files in: /home/leobaro/workspace/labs/fair_spoke_8/fair_spoke_8_leonardo/datacomp_download/wandb/run-20250114_141728-2w6hucrj/files
2025-01-14 14:23:19,081 INFO    SenderThread:31595 [sender.py:_start_run_threads():815] run started: 2w6hucrj with start time 1736860648
2025-01-14 14:23:19,081 INFO    SenderThread:31595 [sender.py:finish():1114] shutting down sender
2025-01-14 14:23:19,081 INFO    SenderThread:31595 [dir_watcher.py:finish():353] shutting down directory watcher
2025-01-14 14:23:20,081 INFO    SenderThread:31595 [dir_watcher.py:finish():383] scan: /home/leobaro/workspace/labs/fair_spoke_8/fair_spoke_8_leonardo/datacomp_download/wandb/run-20250114_141728-2w6hucrj/files
2025-01-14 14:23:20,081 INFO    SenderThread:31595 [dir_watcher.py:finish():397] scan save: /home/leobaro/workspace/labs/fair_spoke_8/fair_spoke_8_leonardo/datacomp_download/wandb/run-20250114_141728-2w6hucrj/files/config.yaml config.yaml
2025-01-14 14:23:20,081 INFO    SenderThread:31595 [file_pusher.py:finish():171] shutting down file pusher
2025-01-14 14:23:20,081 INFO    SenderThread:31595 [file_pusher.py:join():176] waiting for file pusher
2025-01-14 14:23:35,992 INFO    Thread-9  :31595 [upload_job.py:push():138] Uploaded file /home/leobaro/workspace/labs/fair_spoke_8/fair_spoke_8_leonardo/datacomp_download/wandb/run-20250114_141728-2w6hucrj/files/config.yaml
2025-01-14 14:23:44,004 INFO    MainThread:31595 [internal.py:handle_exit():80] Internal process exited
