2025-01-14 14:49:01,603 INFO    MainThread:34486 [wandb_setup.py:_flush():76] Configure stats pid to 34486
2025-01-14 14:49:01,603 INFO    MainThread:34486 [wandb_setup.py:_flush():76] Loading settings from /home/leobaro/.config/wandb/settings
2025-01-14 14:49:01,603 INFO    MainThread:34486 [wandb_setup.py:_flush():76] Loading settings from /home/leobaro/workspace/labs/fair_spoke_8/fair_spoke_8_leonardo/datacomp_download/wandb/settings
2025-01-14 14:49:01,604 INFO    MainThread:34486 [wandb_setup.py:_flush():76] Loading settings from environment variables: {}
2025-01-14 14:49:01,604 INFO    MainThread:34486 [wandb_setup.py:_flush():76] Inferring run settings from compute environment: {'program_relpath': 'fair_spoke_8_leonardo/datacomp_download/download_upstream.py', 'program': '/home/leobaro/workspace/labs/fair_spoke_8/fair_spoke_8_leonardo/datacomp_download/download_upstream.py'}
2025-01-14 14:49:01,604 INFO    MainThread:34486 [wandb_setup.py:_flush():76] Applying login settings: {'anonymous': 'allow'}
2025-01-14 14:49:01,604 INFO    MainThread:34486 [wandb_init.py:_log_setup():461] Logging user logs to /home/leobaro/workspace/labs/fair_spoke_8/fair_spoke_8_leonardo/datacomp_download/wandb/run-20250114_144901-1ppac67y/logs/debug.log
2025-01-14 14:49:01,604 INFO    MainThread:34486 [wandb_init.py:_log_setup():462] Logging internal logs to /home/leobaro/workspace/labs/fair_spoke_8/fair_spoke_8_leonardo/datacomp_download/wandb/run-20250114_144901-1ppac67y/logs/debug-internal.log
2025-01-14 14:49:01,604 INFO    MainThread:34486 [wandb_init.py:init():495] calling init triggers
2025-01-14 14:49:01,604 INFO    MainThread:34486 [wandb_init.py:init():498] wandb.init called with sweep_config: {}
config: {'url_list': '/home/leobaro/Downloads/datasets/web/datacomp/metadata', 'image_size': 512, 'output_folder': '/home/leobaro/Downloads/datasets/web/datacomp/shards', 'processes_count': 16, 'resize_mode': 'keep_ratio_largest', 'resize_only_if_bigger': True, 'upscale_interpolation': 'lanczos', 'downscale_interpolation': 'area', 'encode_quality': 95, 'encode_format': 'jpg', 'skip_reencode': False, 'output_format': 'webdataset', 'input_format': 'parquet', 'url_col': 'url', 'caption_col': 'text', 'bbox_col': 'face_bboxes', 'thread_count': 128, 'number_sample_per_shard': 10000, 'extract_exif': True, 'save_additional_columns': ['uid'], 'timeout': 10, 'enable_wandb': True, 'wandb_project': 'datacomp', 'oom_shard_count': 8, 'compute_hash': 'sha256', 'distributor': 'multiprocessing', 'subjob_size': 1000, 'retries': 5, 'disable_all_reencoding': False, 'min_image_size': 0, 'max_image_area': inf, 'max_aspect_ratio': inf, 'incremental_mode': 'incremental', 'max_shard_retry': 1, 'user_agent_token': None, 'disallowed_header_directives': ['noai', 'noimageai', 'noindex', 'noimageindex']}
2025-01-14 14:49:01,604 INFO    MainThread:34486 [wandb_init.py:init():548] starting backend
2025-01-14 14:49:01,604 INFO    MainThread:34486 [backend.py:_multiprocessing_setup():97] multiprocessing start_methods=fork,spawn,forkserver, using: spawn
2025-01-14 14:49:01,605 INFO    MainThread:34486 [backend.py:ensure_launched():217] starting backend process...
2025-01-14 14:49:01,606 INFO    MainThread:34486 [backend.py:ensure_launched():222] started backend process with pid: 37540
2025-01-14 14:49:01,607 INFO    MainThread:34486 [wandb_init.py:init():558] backend started and connected
2025-01-14 14:49:01,610 INFO    MainThread:34486 [wandb_init.py:init():634] updated telemetry
2025-01-14 14:49:01,616 INFO    MainThread:34486 [wandb_init.py:init():665] communicating run to backend with 30 second timeout
2025-01-14 14:49:12,164 ERROR   Thread-1 (wrapped_target):34486 [retry.py:__call__():132] Retry attempt failed:
Traceback (most recent call last):
  File "/home/leobaro/softwares/miniconda3/envs/datacomp/lib/python3.10/site-packages/urllib3/connectionpool.py", line 703, in urlopen
    httplib_response = self._make_request(
  File "/home/leobaro/softwares/miniconda3/envs/datacomp/lib/python3.10/site-packages/urllib3/connectionpool.py", line 386, in _make_request
    self._validate_conn(conn)
  File "/home/leobaro/softwares/miniconda3/envs/datacomp/lib/python3.10/site-packages/urllib3/connectionpool.py", line 1042, in _validate_conn
    conn.connect()
  File "/home/leobaro/softwares/miniconda3/envs/datacomp/lib/python3.10/site-packages/urllib3/connection.py", line 414, in connect
    self.sock = ssl_wrap_socket(
  File "/home/leobaro/softwares/miniconda3/envs/datacomp/lib/python3.10/site-packages/urllib3/util/ssl_.py", line 449, in ssl_wrap_socket
    ssl_sock = _ssl_wrap_socket_impl(
  File "/home/leobaro/softwares/miniconda3/envs/datacomp/lib/python3.10/site-packages/urllib3/util/ssl_.py", line 493, in _ssl_wrap_socket_impl
    return ssl_context.wrap_socket(sock, server_hostname=server_hostname)
  File "/home/leobaro/softwares/miniconda3/envs/datacomp/lib/python3.10/ssl.py", line 513, in wrap_socket
    return self.sslsocket_class._create(
  File "/home/leobaro/softwares/miniconda3/envs/datacomp/lib/python3.10/ssl.py", line 1071, in _create
    self.do_handshake()
  File "/home/leobaro/softwares/miniconda3/envs/datacomp/lib/python3.10/ssl.py", line 1342, in do_handshake
    self._sslobj.do_handshake()
ssl.SSLEOFError: EOF occurred in violation of protocol (_ssl.c:997)

During handling of the above exception, another exception occurred:

Traceback (most recent call last):
  File "/home/leobaro/softwares/miniconda3/envs/datacomp/lib/python3.10/site-packages/requests/adapters.py", line 489, in send
    resp = conn.urlopen(
  File "/home/leobaro/softwares/miniconda3/envs/datacomp/lib/python3.10/site-packages/urllib3/connectionpool.py", line 787, in urlopen
    retries = retries.increment(
  File "/home/leobaro/softwares/miniconda3/envs/datacomp/lib/python3.10/site-packages/urllib3/util/retry.py", line 592, in increment
    raise MaxRetryError(_pool, url, error or ResponseError(cause))
urllib3.exceptions.MaxRetryError: HTTPSConnectionPool(host='api.wandb.ai', port=443): Max retries exceeded with url: /graphql (Caused by SSLError(SSLEOFError(8, 'EOF occurred in violation of protocol (_ssl.c:997)')))

During handling of the above exception, another exception occurred:

Traceback (most recent call last):
  File "/home/leobaro/softwares/miniconda3/envs/datacomp/lib/python3.10/site-packages/wandb/sdk/lib/retry.py", line 108, in __call__
    result = self._call_fn(*args, **kwargs)
  File "/home/leobaro/softwares/miniconda3/envs/datacomp/lib/python3.10/site-packages/wandb/sdk/internal/internal_api.py", line 158, in execute
    return self.client.execute(*args, **kwargs)
  File "/home/leobaro/softwares/miniconda3/envs/datacomp/lib/python3.10/site-packages/wandb/vendor/gql-0.2.0/wandb_gql/client.py", line 52, in execute
    result = self._get_result(document, *args, **kwargs)
  File "/home/leobaro/softwares/miniconda3/envs/datacomp/lib/python3.10/site-packages/wandb/vendor/gql-0.2.0/wandb_gql/client.py", line 60, in _get_result
    return self.transport.execute(document, *args, **kwargs)
  File "/home/leobaro/softwares/miniconda3/envs/datacomp/lib/python3.10/site-packages/wandb/vendor/gql-0.2.0/wandb_gql/transport/requests.py", line 38, in execute
    request = requests.post(self.url, **post_args)
  File "/home/leobaro/softwares/miniconda3/envs/datacomp/lib/python3.10/site-packages/requests/api.py", line 115, in post
    return request("post", url, data=data, json=json, **kwargs)
  File "/home/leobaro/softwares/miniconda3/envs/datacomp/lib/python3.10/site-packages/requests/api.py", line 59, in request
    return session.request(method=method, url=url, **kwargs)
  File "/home/leobaro/softwares/miniconda3/envs/datacomp/lib/python3.10/site-packages/requests/sessions.py", line 587, in request
    resp = self.send(prep, **send_kwargs)
  File "/home/leobaro/softwares/miniconda3/envs/datacomp/lib/python3.10/site-packages/requests/sessions.py", line 701, in send
    r = adapter.send(request, **kwargs)
  File "/home/leobaro/softwares/miniconda3/envs/datacomp/lib/python3.10/site-packages/requests/adapters.py", line 563, in send
    raise SSLError(e, request=request)
requests.exceptions.SSLError: HTTPSConnectionPool(host='api.wandb.ai', port=443): Max retries exceeded with url: /graphql (Caused by SSLError(SSLEOFError(8, 'EOF occurred in violation of protocol (_ssl.c:997)')))
2025-01-14 14:49:31,617 INFO    MainThread:34486 [interface_shared.py:_communicate_run():326] couldn't get run from backend
2025-01-14 14:49:31,617 ERROR   MainThread:34486 [wandb_init.py:init():674] backend process timed out
2025-01-14 14:49:31,617 ERROR   MainThread:34486 [wandb_init.py:init():685] encountered error: Error communicating with wandb process
try: wandb.init(settings=wandb.Settings(start_method='fork'))
or:  wandb.init(settings=wandb.Settings(start_method='thread'))
For more info see: https://docs.wandb.ai/library/init#init-start-error
2025-01-14 14:54:41,077 INFO    MainThread:34486 [wandb_init.py:teardown():302] tearing down wandb.init
