2025-01-14 14:49:02,180 INFO    MainThread:37540 [internal.py:wandb_internal():90] W&B internal server running at pid: 37540, started at: 2025-01-14 14:49:02.180464
2025-01-14 14:49:02,184 INFO    WriterThread:37540 [datastore.py:open_for_write():75] open: /home/leobaro/workspace/labs/fair_spoke_8/fair_spoke_8_leonardo/datacomp_download/wandb/run-20250114_144901-1ppac67y/run-1ppac67y.wandb
2025-01-14 14:49:02,345 DEBUG   SenderThread:37540 [sender.py:send():236] send: header
2025-01-14 14:49:02,345 DEBUG   SenderThread:37540 [sender.py:send():236] send: run
2025-01-14 14:49:22,921 ERROR   SenderThread:37540 [retry.py:__call__():132] Retry attempt failed:
Traceback (most recent call last):
  File "/home/leobaro/softwares/miniconda3/envs/datacomp/lib/python3.10/site-packages/urllib3/connectionpool.py", line 703, in urlopen
    httplib_response = self._make_request(
  File "/home/leobaro/softwares/miniconda3/envs/datacomp/lib/python3.10/site-packages/urllib3/connectionpool.py", line 386, in _make_request
    self._validate_conn(conn)
  File "/home/leobaro/softwares/miniconda3/envs/datacomp/lib/python3.10/site-packages/urllib3/connectionpool.py", line 1042, in _validate_conn
    conn.connect()
  File "/home/leobaro/softwares/miniconda3/envs/datacomp/lib/python3.10/site-packages/urllib3/connection.py", line 414, in connect
    self.sock = ssl_wrap_socket(
  File "/home/leobaro/softwares/miniconda3/envs/datacomp/lib/python3.10/site-packages/urllib3/util/ssl_.py", line 449, in ssl_wrap_socket
    ssl_sock = _ssl_wrap_socket_impl(
  File "/home/leobaro/softwares/miniconda3/envs/datacomp/lib/python3.10/site-packages/urllib3/util/ssl_.py", line 493, in _ssl_wrap_socket_impl
    return ssl_context.wrap_socket(sock, server_hostname=server_hostname)
  File "/home/leobaro/softwares/miniconda3/envs/datacomp/lib/python3.10/ssl.py", line 513, in wrap_socket
    return self.sslsocket_class._create(
  File "/home/leobaro/softwares/miniconda3/envs/datacomp/lib/python3.10/ssl.py", line 1071, in _create
    self.do_handshake()
  File "/home/leobaro/softwares/miniconda3/envs/datacomp/lib/python3.10/ssl.py", line 1342, in do_handshake
    self._sslobj.do_handshake()
ssl.SSLEOFError: EOF occurred in violation of protocol (_ssl.c:997)

During handling of the above exception, another exception occurred:

Traceback (most recent call last):
  File "/home/leobaro/softwares/miniconda3/envs/datacomp/lib/python3.10/site-packages/requests/adapters.py", line 489, in send
    resp = conn.urlopen(
  File "/home/leobaro/softwares/miniconda3/envs/datacomp/lib/python3.10/site-packages/urllib3/connectionpool.py", line 787, in urlopen
    retries = retries.increment(
  File "/home/leobaro/softwares/miniconda3/envs/datacomp/lib/python3.10/site-packages/urllib3/util/retry.py", line 592, in increment
    raise MaxRetryError(_pool, url, error or ResponseError(cause))
urllib3.exceptions.MaxRetryError: HTTPSConnectionPool(host='api.wandb.ai', port=443): Max retries exceeded with url: /graphql (Caused by SSLError(SSLEOFError(8, 'EOF occurred in violation of protocol (_ssl.c:997)')))

During handling of the above exception, another exception occurred:

Traceback (most recent call last):
  File "/home/leobaro/softwares/miniconda3/envs/datacomp/lib/python3.10/site-packages/wandb/sdk/lib/retry.py", line 108, in __call__
    result = self._call_fn(*args, **kwargs)
  File "/home/leobaro/softwares/miniconda3/envs/datacomp/lib/python3.10/site-packages/wandb/sdk/internal/internal_api.py", line 158, in execute
    return self.client.execute(*args, **kwargs)
  File "/home/leobaro/softwares/miniconda3/envs/datacomp/lib/python3.10/site-packages/wandb/vendor/gql-0.2.0/wandb_gql/client.py", line 52, in execute
    result = self._get_result(document, *args, **kwargs)
  File "/home/leobaro/softwares/miniconda3/envs/datacomp/lib/python3.10/site-packages/wandb/vendor/gql-0.2.0/wandb_gql/client.py", line 60, in _get_result
    return self.transport.execute(document, *args, **kwargs)
  File "/home/leobaro/softwares/miniconda3/envs/datacomp/lib/python3.10/site-packages/wandb/vendor/gql-0.2.0/wandb_gql/transport/requests.py", line 38, in execute
    request = requests.post(self.url, **post_args)
  File "/home/leobaro/softwares/miniconda3/envs/datacomp/lib/python3.10/site-packages/requests/api.py", line 115, in post
    return request("post", url, data=data, json=json, **kwargs)
  File "/home/leobaro/softwares/miniconda3/envs/datacomp/lib/python3.10/site-packages/requests/api.py", line 59, in request
    return session.request(method=method, url=url, **kwargs)
  File "/home/leobaro/softwares/miniconda3/envs/datacomp/lib/python3.10/site-packages/requests/sessions.py", line 587, in request
    resp = self.send(prep, **send_kwargs)
  File "/home/leobaro/softwares/miniconda3/envs/datacomp/lib/python3.10/site-packages/requests/sessions.py", line 701, in send
    r = adapter.send(request, **kwargs)
  File "/home/leobaro/softwares/miniconda3/envs/datacomp/lib/python3.10/site-packages/requests/adapters.py", line 563, in send
    raise SSLError(e, request=request)
requests.exceptions.SSLError: HTTPSConnectionPool(host='api.wandb.ai', port=443): Max retries exceeded with url: /graphql (Caused by SSLError(SSLEOFError(8, 'EOF occurred in violation of protocol (_ssl.c:997)')))
2025-01-14 14:49:31,618 DEBUG   HandlerThread:37540 [handler.py:handle_request():140] handle_request: shutdown
2025-01-14 14:49:31,618 INFO    HandlerThread:37540 [handler.py:finish():806] shutting down handler
2025-01-14 14:49:32,191 INFO    WriterThread:37540 [datastore.py:close():279] close: /home/leobaro/workspace/labs/fair_spoke_8/fair_spoke_8_leonardo/datacomp_download/wandb/run-20250114_144901-1ppac67y/run-1ppac67y.wandb
2025-01-14 14:49:34,954 INFO    SenderThread:37540 [dir_watcher.py:__init__():216] watching files in: /home/leobaro/workspace/labs/fair_spoke_8/fair_spoke_8_leonardo/datacomp_download/wandb/run-20250114_144901-1ppac67y/files
2025-01-14 14:49:34,954 INFO    SenderThread:37540 [sender.py:_start_run_threads():815] run started: 1ppac67y with start time 1736862541
2025-01-14 14:49:34,954 INFO    SenderThread:37540 [sender.py:finish():1114] shutting down sender
2025-01-14 14:49:34,954 INFO    SenderThread:37540 [dir_watcher.py:finish():353] shutting down directory watcher
2025-01-14 14:49:35,954 INFO    SenderThread:37540 [dir_watcher.py:finish():383] scan: /home/leobaro/workspace/labs/fair_spoke_8/fair_spoke_8_leonardo/datacomp_download/wandb/run-20250114_144901-1ppac67y/files
2025-01-14 14:49:35,954 INFO    SenderThread:37540 [dir_watcher.py:finish():397] scan save: /home/leobaro/workspace/labs/fair_spoke_8/fair_spoke_8_leonardo/datacomp_download/wandb/run-20250114_144901-1ppac67y/files/config.yaml config.yaml
2025-01-14 14:49:35,954 INFO    SenderThread:37540 [file_pusher.py:finish():171] shutting down file pusher
2025-01-14 14:49:35,955 INFO    SenderThread:37540 [file_pusher.py:join():176] waiting for file pusher
2025-01-14 14:49:47,617 ERROR   Thread-9  :37540 [retry.py:__call__():132] Retry attempt failed:
Traceback (most recent call last):
  File "/home/leobaro/softwares/miniconda3/envs/datacomp/lib/python3.10/site-packages/urllib3/connectionpool.py", line 703, in urlopen
    httplib_response = self._make_request(
  File "/home/leobaro/softwares/miniconda3/envs/datacomp/lib/python3.10/site-packages/urllib3/connectionpool.py", line 386, in _make_request
    self._validate_conn(conn)
  File "/home/leobaro/softwares/miniconda3/envs/datacomp/lib/python3.10/site-packages/urllib3/connectionpool.py", line 1042, in _validate_conn
    conn.connect()
  File "/home/leobaro/softwares/miniconda3/envs/datacomp/lib/python3.10/site-packages/urllib3/connection.py", line 414, in connect
    self.sock = ssl_wrap_socket(
  File "/home/leobaro/softwares/miniconda3/envs/datacomp/lib/python3.10/site-packages/urllib3/util/ssl_.py", line 449, in ssl_wrap_socket
    ssl_sock = _ssl_wrap_socket_impl(
  File "/home/leobaro/softwares/miniconda3/envs/datacomp/lib/python3.10/site-packages/urllib3/util/ssl_.py", line 493, in _ssl_wrap_socket_impl
    return ssl_context.wrap_socket(sock, server_hostname=server_hostname)
  File "/home/leobaro/softwares/miniconda3/envs/datacomp/lib/python3.10/ssl.py", line 513, in wrap_socket
    return self.sslsocket_class._create(
  File "/home/leobaro/softwares/miniconda3/envs/datacomp/lib/python3.10/ssl.py", line 1071, in _create
    self.do_handshake()
  File "/home/leobaro/softwares/miniconda3/envs/datacomp/lib/python3.10/ssl.py", line 1342, in do_handshake
    self._sslobj.do_handshake()
ssl.SSLEOFError: EOF occurred in violation of protocol (_ssl.c:997)

During handling of the above exception, another exception occurred:

Traceback (most recent call last):
  File "/home/leobaro/softwares/miniconda3/envs/datacomp/lib/python3.10/site-packages/requests/adapters.py", line 489, in send
    resp = conn.urlopen(
  File "/home/leobaro/softwares/miniconda3/envs/datacomp/lib/python3.10/site-packages/urllib3/connectionpool.py", line 787, in urlopen
    retries = retries.increment(
  File "/home/leobaro/softwares/miniconda3/envs/datacomp/lib/python3.10/site-packages/urllib3/util/retry.py", line 592, in increment
    raise MaxRetryError(_pool, url, error or ResponseError(cause))
urllib3.exceptions.MaxRetryError: HTTPSConnectionPool(host='api.wandb.ai', port=443): Max retries exceeded with url: /graphql (Caused by SSLError(SSLEOFError(8, 'EOF occurred in violation of protocol (_ssl.c:997)')))

During handling of the above exception, another exception occurred:

Traceback (most recent call last):
  File "/home/leobaro/softwares/miniconda3/envs/datacomp/lib/python3.10/site-packages/wandb/sdk/lib/retry.py", line 108, in __call__
    result = self._call_fn(*args, **kwargs)
  File "/home/leobaro/softwares/miniconda3/envs/datacomp/lib/python3.10/site-packages/wandb/sdk/internal/internal_api.py", line 158, in execute
    return self.client.execute(*args, **kwargs)
  File "/home/leobaro/softwares/miniconda3/envs/datacomp/lib/python3.10/site-packages/wandb/vendor/gql-0.2.0/wandb_gql/client.py", line 52, in execute
    result = self._get_result(document, *args, **kwargs)
  File "/home/leobaro/softwares/miniconda3/envs/datacomp/lib/python3.10/site-packages/wandb/vendor/gql-0.2.0/wandb_gql/client.py", line 60, in _get_result
    return self.transport.execute(document, *args, **kwargs)
  File "/home/leobaro/softwares/miniconda3/envs/datacomp/lib/python3.10/site-packages/wandb/vendor/gql-0.2.0/wandb_gql/transport/requests.py", line 38, in execute
    request = requests.post(self.url, **post_args)
  File "/home/leobaro/softwares/miniconda3/envs/datacomp/lib/python3.10/site-packages/requests/api.py", line 115, in post
    return request("post", url, data=data, json=json, **kwargs)
  File "/home/leobaro/softwares/miniconda3/envs/datacomp/lib/python3.10/site-packages/requests/api.py", line 59, in request
    return session.request(method=method, url=url, **kwargs)
  File "/home/leobaro/softwares/miniconda3/envs/datacomp/lib/python3.10/site-packages/requests/sessions.py", line 587, in request
    resp = self.send(prep, **send_kwargs)
  File "/home/leobaro/softwares/miniconda3/envs/datacomp/lib/python3.10/site-packages/requests/sessions.py", line 701, in send
    r = adapter.send(request, **kwargs)
  File "/home/leobaro/softwares/miniconda3/envs/datacomp/lib/python3.10/site-packages/requests/adapters.py", line 563, in send
    raise SSLError(e, request=request)
requests.exceptions.SSLError: HTTPSConnectionPool(host='api.wandb.ai', port=443): Max retries exceeded with url: /graphql (Caused by SSLError(SSLEOFError(8, 'EOF occurred in violation of protocol (_ssl.c:997)')))
2025-01-14 14:50:13,994 WARNING FileStreamThread:37540 [file_stream.py:request_with_retry():589] requests_with_retry encountered retryable exception: HTTPSConnectionPool(host='api.wandb.ai', port=443): Max retries exceeded with url: /files/leobaro/datacomp/1ppac67y/file_stream (Caused by SSLError(SSLEOFError(8, 'EOF occurred in violation of protocol (_ssl.c:997)'))). func: <bound method Session.post of <requests.sessions.Session object at 0x7b141a70bf70>>, args: ('https://api.wandb.ai/files/leobaro/datacomp/1ppac67y/file_stream',), kwargs: {'json': {'complete': False, 'failed': False, 'dropped': 0, 'uploaded': []}}
2025-01-14 14:50:17,444 WARNING FileStreamThread:37540 [file_stream.py:request_with_retry():589] requests_with_retry encountered retryable exception: HTTPSConnectionPool(host='api.wandb.ai', port=443): Max retries exceeded with url: /files/leobaro/datacomp/1ppac67y/file_stream (Caused by SSLError(SSLEOFError(8, 'EOF occurred in violation of protocol (_ssl.c:997)'))). func: <bound method Session.post of <requests.sessions.Session object at 0x7b141a70bf70>>, args: ('https://api.wandb.ai/files/leobaro/datacomp/1ppac67y/file_stream',), kwargs: {'json': {'complete': False, 'failed': False, 'dropped': 0, 'uploaded': []}}
2025-01-14 14:50:23,421 WARNING FileStreamThread:37540 [file_stream.py:request_with_retry():589] requests_with_retry encountered retryable exception: HTTPSConnectionPool(host='api.wandb.ai', port=443): Max retries exceeded with url: /files/leobaro/datacomp/1ppac67y/file_stream (Caused by SSLError(SSLEOFError(8, 'EOF occurred in violation of protocol (_ssl.c:997)'))). func: <bound method Session.post of <requests.sessions.Session object at 0x7b141a70bf70>>, args: ('https://api.wandb.ai/files/leobaro/datacomp/1ppac67y/file_stream',), kwargs: {'json': {'complete': False, 'failed': False, 'dropped': 0, 'uploaded': []}}
2025-01-14 14:50:54,025 ERROR   Thread-9  :37540 [internal_api.py:upload_file():1694] upload_file exception https://storage.googleapis.com/wandb-production.appspot.com/leobaro/datacomp/1ppac67y/config.yaml?Expires=1736949037&GoogleAccessId=gorilla-files-url-signer-man%40wandb-production.iam.gserviceaccount.com&Signature=bSto9X6Yu01QYGLcQoa%2FynccrCIUBbFBGgz1wSE5jkgjj2disErKVQYteWgyETzaVcKQBvNv0mmlhSKkico50VHkeTn78RFW%2FjFD6MtwmFauSceOqyresu8VJOS%2F9Ftqbx7D3vACtjQBomGH82FMbRGOuIO7XLz4%2F55PFi74XFZAkmkiXwytrx1vYfvum161iO2KVyTwA545ZY2ez%2FadM77%2FILcNgchtPrynQnLg%2BV0ejr9LfgguAunHnKQU7ko02UNotRLTDxFLvQ3e70suP7IiX6EtDIp9OqW70EeKL45Qx51gXoulkD7alkNZ7FtKczEui6FTvlI1XJ75xiIGCw%3D%3D: ('Connection aborted.', ConnectionResetError(104, 'Connection reset by peer'))
2025-01-14 14:50:54,025 ERROR   Thread-9  :37540 [internal_api.py:upload_file():1696] upload_file request headers: {'User-Agent': 'python-requests/2.28.1', 'Accept-Encoding': 'gzip, deflate', 'Accept': '*/*', 'Connection': 'keep-alive', 'Content-Length': '2106'}
2025-01-14 14:50:54,025 ERROR   Thread-9  :37540 [internal_api.py:upload_file():1698] upload_file response body: 
2025-01-14 14:50:54,159 WARNING FileStreamThread:37540 [file_stream.py:request_with_retry():589] requests_with_retry encountered retryable exception: ('Connection aborted.', ConnectionResetError(104, 'Connection reset by peer')). func: <bound method Session.post of <requests.sessions.Session object at 0x7b141a70bf70>>, args: ('https://api.wandb.ai/files/leobaro/datacomp/1ppac67y/file_stream',), kwargs: {'json': {'complete': False, 'failed': False, 'dropped': 0, 'uploaded': []}}
2025-01-14 14:50:56,211 ERROR   Thread-9  :37540 [internal_api.py:upload_file():1694] upload_file exception https://storage.googleapis.com/wandb-production.appspot.com/leobaro/datacomp/1ppac67y/config.yaml?Expires=1736949037&GoogleAccessId=gorilla-files-url-signer-man%40wandb-production.iam.gserviceaccount.com&Signature=bSto9X6Yu01QYGLcQoa%2FynccrCIUBbFBGgz1wSE5jkgjj2disErKVQYteWgyETzaVcKQBvNv0mmlhSKkico50VHkeTn78RFW%2FjFD6MtwmFauSceOqyresu8VJOS%2F9Ftqbx7D3vACtjQBomGH82FMbRGOuIO7XLz4%2F55PFi74XFZAkmkiXwytrx1vYfvum161iO2KVyTwA545ZY2ez%2FadM77%2FILcNgchtPrynQnLg%2BV0ejr9LfgguAunHnKQU7ko02UNotRLTDxFLvQ3e70suP7IiX6EtDIp9OqW70EeKL45Qx51gXoulkD7alkNZ7FtKczEui6FTvlI1XJ75xiIGCw%3D%3D: HTTPSConnectionPool(host='storage.googleapis.com', port=443): Max retries exceeded with url: /wandb-production.appspot.com/leobaro/datacomp/1ppac67y/config.yaml?Expires=1736949037&GoogleAccessId=gorilla-files-url-signer-man%40wandb-production.iam.gserviceaccount.com&Signature=bSto9X6Yu01QYGLcQoa%2FynccrCIUBbFBGgz1wSE5jkgjj2disErKVQYteWgyETzaVcKQBvNv0mmlhSKkico50VHkeTn78RFW%2FjFD6MtwmFauSceOqyresu8VJOS%2F9Ftqbx7D3vACtjQBomGH82FMbRGOuIO7XLz4%2F55PFi74XFZAkmkiXwytrx1vYfvum161iO2KVyTwA545ZY2ez%2FadM77%2FILcNgchtPrynQnLg%2BV0ejr9LfgguAunHnKQU7ko02UNotRLTDxFLvQ3e70suP7IiX6EtDIp9OqW70EeKL45Qx51gXoulkD7alkNZ7FtKczEui6FTvlI1XJ75xiIGCw%3D%3D (Caused by SSLError(SSLEOFError(8, 'EOF occurred in violation of protocol (_ssl.c:997)')))
2025-01-14 14:50:56,211 ERROR   Thread-9  :37540 [internal_api.py:upload_file():1696] upload_file request headers: {'User-Agent': 'python-requests/2.28.1', 'Accept-Encoding': 'gzip, deflate', 'Accept': '*/*', 'Connection': 'keep-alive', 'Content-Length': '2106'}
2025-01-14 14:50:56,211 ERROR   Thread-9  :37540 [internal_api.py:upload_file():1698] upload_file response body: 
2025-01-14 14:51:14,150 ERROR   Thread-9  :37540 [internal_api.py:upload_file():1694] upload_file exception https://storage.googleapis.com/wandb-production.appspot.com/leobaro/datacomp/1ppac67y/config.yaml?Expires=1736949037&GoogleAccessId=gorilla-files-url-signer-man%40wandb-production.iam.gserviceaccount.com&Signature=bSto9X6Yu01QYGLcQoa%2FynccrCIUBbFBGgz1wSE5jkgjj2disErKVQYteWgyETzaVcKQBvNv0mmlhSKkico50VHkeTn78RFW%2FjFD6MtwmFauSceOqyresu8VJOS%2F9Ftqbx7D3vACtjQBomGH82FMbRGOuIO7XLz4%2F55PFi74XFZAkmkiXwytrx1vYfvum161iO2KVyTwA545ZY2ez%2FadM77%2FILcNgchtPrynQnLg%2BV0ejr9LfgguAunHnKQU7ko02UNotRLTDxFLvQ3e70suP7IiX6EtDIp9OqW70EeKL45Qx51gXoulkD7alkNZ7FtKczEui6FTvlI1XJ75xiIGCw%3D%3D: ('Connection aborted.', ConnectionResetError(104, 'Connection reset by peer'))
2025-01-14 14:51:14,150 ERROR   Thread-9  :37540 [internal_api.py:upload_file():1696] upload_file request headers: {'User-Agent': 'python-requests/2.28.1', 'Accept-Encoding': 'gzip, deflate', 'Accept': '*/*', 'Connection': 'keep-alive', 'Content-Length': '2106'}
2025-01-14 14:51:14,151 ERROR   Thread-9  :37540 [internal_api.py:upload_file():1698] upload_file response body: 
2025-01-14 14:51:14,151 ERROR   Thread-9  :37540 [retry.py:__call__():132] Retry attempt failed:
Traceback (most recent call last):
  File "/home/leobaro/softwares/miniconda3/envs/datacomp/lib/python3.10/site-packages/urllib3/connectionpool.py", line 703, in urlopen
    httplib_response = self._make_request(
  File "/home/leobaro/softwares/miniconda3/envs/datacomp/lib/python3.10/site-packages/urllib3/connectionpool.py", line 386, in _make_request
    self._validate_conn(conn)
  File "/home/leobaro/softwares/miniconda3/envs/datacomp/lib/python3.10/site-packages/urllib3/connectionpool.py", line 1042, in _validate_conn
    conn.connect()
  File "/home/leobaro/softwares/miniconda3/envs/datacomp/lib/python3.10/site-packages/urllib3/connection.py", line 414, in connect
    self.sock = ssl_wrap_socket(
  File "/home/leobaro/softwares/miniconda3/envs/datacomp/lib/python3.10/site-packages/urllib3/util/ssl_.py", line 449, in ssl_wrap_socket
    ssl_sock = _ssl_wrap_socket_impl(
  File "/home/leobaro/softwares/miniconda3/envs/datacomp/lib/python3.10/site-packages/urllib3/util/ssl_.py", line 493, in _ssl_wrap_socket_impl
    return ssl_context.wrap_socket(sock, server_hostname=server_hostname)
  File "/home/leobaro/softwares/miniconda3/envs/datacomp/lib/python3.10/ssl.py", line 513, in wrap_socket
    return self.sslsocket_class._create(
  File "/home/leobaro/softwares/miniconda3/envs/datacomp/lib/python3.10/ssl.py", line 1071, in _create
    self.do_handshake()
  File "/home/leobaro/softwares/miniconda3/envs/datacomp/lib/python3.10/ssl.py", line 1342, in do_handshake
    self._sslobj.do_handshake()
ConnectionResetError: [Errno 104] Connection reset by peer

During handling of the above exception, another exception occurred:

Traceback (most recent call last):
  File "/home/leobaro/softwares/miniconda3/envs/datacomp/lib/python3.10/site-packages/requests/adapters.py", line 489, in send
    resp = conn.urlopen(
  File "/home/leobaro/softwares/miniconda3/envs/datacomp/lib/python3.10/site-packages/urllib3/connectionpool.py", line 787, in urlopen
    retries = retries.increment(
  File "/home/leobaro/softwares/miniconda3/envs/datacomp/lib/python3.10/site-packages/urllib3/util/retry.py", line 550, in increment
    raise six.reraise(type(error), error, _stacktrace)
  File "/home/leobaro/softwares/miniconda3/envs/datacomp/lib/python3.10/site-packages/urllib3/packages/six.py", line 769, in reraise
    raise value.with_traceback(tb)
  File "/home/leobaro/softwares/miniconda3/envs/datacomp/lib/python3.10/site-packages/urllib3/connectionpool.py", line 703, in urlopen
    httplib_response = self._make_request(
  File "/home/leobaro/softwares/miniconda3/envs/datacomp/lib/python3.10/site-packages/urllib3/connectionpool.py", line 386, in _make_request
    self._validate_conn(conn)
  File "/home/leobaro/softwares/miniconda3/envs/datacomp/lib/python3.10/site-packages/urllib3/connectionpool.py", line 1042, in _validate_conn
    conn.connect()
  File "/home/leobaro/softwares/miniconda3/envs/datacomp/lib/python3.10/site-packages/urllib3/connection.py", line 414, in connect
    self.sock = ssl_wrap_socket(
  File "/home/leobaro/softwares/miniconda3/envs/datacomp/lib/python3.10/site-packages/urllib3/util/ssl_.py", line 449, in ssl_wrap_socket
    ssl_sock = _ssl_wrap_socket_impl(
  File "/home/leobaro/softwares/miniconda3/envs/datacomp/lib/python3.10/site-packages/urllib3/util/ssl_.py", line 493, in _ssl_wrap_socket_impl
    return ssl_context.wrap_socket(sock, server_hostname=server_hostname)
  File "/home/leobaro/softwares/miniconda3/envs/datacomp/lib/python3.10/ssl.py", line 513, in wrap_socket
    return self.sslsocket_class._create(
  File "/home/leobaro/softwares/miniconda3/envs/datacomp/lib/python3.10/ssl.py", line 1071, in _create
    self.do_handshake()
  File "/home/leobaro/softwares/miniconda3/envs/datacomp/lib/python3.10/ssl.py", line 1342, in do_handshake
    self._sslobj.do_handshake()
urllib3.exceptions.ProtocolError: ('Connection aborted.', ConnectionResetError(104, 'Connection reset by peer'))

During handling of the above exception, another exception occurred:

Traceback (most recent call last):
  File "/home/leobaro/softwares/miniconda3/envs/datacomp/lib/python3.10/site-packages/wandb/sdk/internal/internal_api.py", line 1691, in upload_file
    response = requests.put(url, data=progress, headers=extra_headers)
  File "/home/leobaro/softwares/miniconda3/envs/datacomp/lib/python3.10/site-packages/requests/api.py", line 130, in put
    return request("put", url, data=data, **kwargs)
  File "/home/leobaro/softwares/miniconda3/envs/datacomp/lib/python3.10/site-packages/requests/api.py", line 59, in request
    return session.request(method=method, url=url, **kwargs)
  File "/home/leobaro/softwares/miniconda3/envs/datacomp/lib/python3.10/site-packages/requests/sessions.py", line 587, in request
    resp = self.send(prep, **send_kwargs)
  File "/home/leobaro/softwares/miniconda3/envs/datacomp/lib/python3.10/site-packages/requests/sessions.py", line 701, in send
    r = adapter.send(request, **kwargs)
  File "/home/leobaro/softwares/miniconda3/envs/datacomp/lib/python3.10/site-packages/requests/adapters.py", line 547, in send
    raise ConnectionError(err, request=request)
requests.exceptions.ConnectionError: ('Connection aborted.', ConnectionResetError(104, 'Connection reset by peer'))

During handling of the above exception, another exception occurred:

Traceback (most recent call last):
  File "/home/leobaro/softwares/miniconda3/envs/datacomp/lib/python3.10/site-packages/wandb/sdk/lib/retry.py", line 108, in __call__
    result = self._call_fn(*args, **kwargs)
  File "/home/leobaro/softwares/miniconda3/envs/datacomp/lib/python3.10/site-packages/wandb/sdk/internal/internal_api.py", line 1707, in upload_file
    raise e.with_traceback(sys.exc_info()[2])
  File "/home/leobaro/softwares/miniconda3/envs/datacomp/lib/python3.10/site-packages/wandb/sdk/internal/internal_api.py", line 1691, in upload_file
    response = requests.put(url, data=progress, headers=extra_headers)
  File "/home/leobaro/softwares/miniconda3/envs/datacomp/lib/python3.10/site-packages/requests/api.py", line 130, in put
    return request("put", url, data=data, **kwargs)
  File "/home/leobaro/softwares/miniconda3/envs/datacomp/lib/python3.10/site-packages/requests/api.py", line 59, in request
    return session.request(method=method, url=url, **kwargs)
  File "/home/leobaro/softwares/miniconda3/envs/datacomp/lib/python3.10/site-packages/requests/sessions.py", line 587, in request
    resp = self.send(prep, **send_kwargs)
  File "/home/leobaro/softwares/miniconda3/envs/datacomp/lib/python3.10/site-packages/requests/sessions.py", line 701, in send
    r = adapter.send(request, **kwargs)
  File "/home/leobaro/softwares/miniconda3/envs/datacomp/lib/python3.10/site-packages/requests/adapters.py", line 547, in send
    raise ConnectionError(err, request=request)
wandb.sdk.lib.retry.TransientError: None
2025-01-14 14:51:39,060 ERROR   Thread-9  :37540 [internal_api.py:upload_file():1694] upload_file exception https://storage.googleapis.com/wandb-production.appspot.com/leobaro/datacomp/1ppac67y/config.yaml?Expires=1736949037&GoogleAccessId=gorilla-files-url-signer-man%40wandb-production.iam.gserviceaccount.com&Signature=bSto9X6Yu01QYGLcQoa%2FynccrCIUBbFBGgz1wSE5jkgjj2disErKVQYteWgyETzaVcKQBvNv0mmlhSKkico50VHkeTn78RFW%2FjFD6MtwmFauSceOqyresu8VJOS%2F9Ftqbx7D3vACtjQBomGH82FMbRGOuIO7XLz4%2F55PFi74XFZAkmkiXwytrx1vYfvum161iO2KVyTwA545ZY2ez%2FadM77%2FILcNgchtPrynQnLg%2BV0ejr9LfgguAunHnKQU7ko02UNotRLTDxFLvQ3e70suP7IiX6EtDIp9OqW70EeKL45Qx51gXoulkD7alkNZ7FtKczEui6FTvlI1XJ75xiIGCw%3D%3D: ('Connection aborted.', ConnectionResetError(104, 'Connection reset by peer'))
2025-01-14 14:51:39,061 ERROR   Thread-9  :37540 [internal_api.py:upload_file():1696] upload_file request headers: {'User-Agent': 'python-requests/2.28.1', 'Accept-Encoding': 'gzip, deflate', 'Accept': '*/*', 'Connection': 'keep-alive', 'Content-Length': '2106'}
2025-01-14 14:51:39,061 ERROR   Thread-9  :37540 [internal_api.py:upload_file():1698] upload_file response body: 
2025-01-14 14:51:49,615 ERROR   Thread-9  :37540 [internal_api.py:upload_file():1694] upload_file exception https://storage.googleapis.com/wandb-production.appspot.com/leobaro/datacomp/1ppac67y/config.yaml?Expires=1736949037&GoogleAccessId=gorilla-files-url-signer-man%40wandb-production.iam.gserviceaccount.com&Signature=bSto9X6Yu01QYGLcQoa%2FynccrCIUBbFBGgz1wSE5jkgjj2disErKVQYteWgyETzaVcKQBvNv0mmlhSKkico50VHkeTn78RFW%2FjFD6MtwmFauSceOqyresu8VJOS%2F9Ftqbx7D3vACtjQBomGH82FMbRGOuIO7XLz4%2F55PFi74XFZAkmkiXwytrx1vYfvum161iO2KVyTwA545ZY2ez%2FadM77%2FILcNgchtPrynQnLg%2BV0ejr9LfgguAunHnKQU7ko02UNotRLTDxFLvQ3e70suP7IiX6EtDIp9OqW70EeKL45Qx51gXoulkD7alkNZ7FtKczEui6FTvlI1XJ75xiIGCw%3D%3D: HTTPSConnectionPool(host='storage.googleapis.com', port=443): Max retries exceeded with url: /wandb-production.appspot.com/leobaro/datacomp/1ppac67y/config.yaml?Expires=1736949037&GoogleAccessId=gorilla-files-url-signer-man%40wandb-production.iam.gserviceaccount.com&Signature=bSto9X6Yu01QYGLcQoa%2FynccrCIUBbFBGgz1wSE5jkgjj2disErKVQYteWgyETzaVcKQBvNv0mmlhSKkico50VHkeTn78RFW%2FjFD6MtwmFauSceOqyresu8VJOS%2F9Ftqbx7D3vACtjQBomGH82FMbRGOuIO7XLz4%2F55PFi74XFZAkmkiXwytrx1vYfvum161iO2KVyTwA545ZY2ez%2FadM77%2FILcNgchtPrynQnLg%2BV0ejr9LfgguAunHnKQU7ko02UNotRLTDxFLvQ3e70suP7IiX6EtDIp9OqW70EeKL45Qx51gXoulkD7alkNZ7FtKczEui6FTvlI1XJ75xiIGCw%3D%3D (Caused by SSLError(SSLEOFError(8, 'EOF occurred in violation of protocol (_ssl.c:997)')))
2025-01-14 14:51:49,615 ERROR   Thread-9  :37540 [internal_api.py:upload_file():1696] upload_file request headers: {'User-Agent': 'python-requests/2.28.1', 'Accept-Encoding': 'gzip, deflate', 'Accept': '*/*', 'Connection': 'keep-alive', 'Content-Length': '2106'}
2025-01-14 14:51:49,616 ERROR   Thread-9  :37540 [internal_api.py:upload_file():1698] upload_file response body: 
2025-01-14 14:52:24,234 ERROR   Thread-9  :37540 [internal_api.py:upload_file():1694] upload_file exception https://storage.googleapis.com/wandb-production.appspot.com/leobaro/datacomp/1ppac67y/config.yaml?Expires=1736949037&GoogleAccessId=gorilla-files-url-signer-man%40wandb-production.iam.gserviceaccount.com&Signature=bSto9X6Yu01QYGLcQoa%2FynccrCIUBbFBGgz1wSE5jkgjj2disErKVQYteWgyETzaVcKQBvNv0mmlhSKkico50VHkeTn78RFW%2FjFD6MtwmFauSceOqyresu8VJOS%2F9Ftqbx7D3vACtjQBomGH82FMbRGOuIO7XLz4%2F55PFi74XFZAkmkiXwytrx1vYfvum161iO2KVyTwA545ZY2ez%2FadM77%2FILcNgchtPrynQnLg%2BV0ejr9LfgguAunHnKQU7ko02UNotRLTDxFLvQ3e70suP7IiX6EtDIp9OqW70EeKL45Qx51gXoulkD7alkNZ7FtKczEui6FTvlI1XJ75xiIGCw%3D%3D: ('Connection aborted.', ConnectionResetError(104, 'Connection reset by peer'))
2025-01-14 14:52:24,234 ERROR   Thread-9  :37540 [internal_api.py:upload_file():1696] upload_file request headers: {'User-Agent': 'python-requests/2.28.1', 'Accept-Encoding': 'gzip, deflate', 'Accept': '*/*', 'Connection': 'keep-alive', 'Content-Length': '2106'}
2025-01-14 14:52:24,234 ERROR   Thread-9  :37540 [internal_api.py:upload_file():1698] upload_file response body: 
2025-01-14 14:53:24,298 ERROR   Thread-9  :37540 [internal_api.py:upload_file():1694] upload_file exception https://storage.googleapis.com/wandb-production.appspot.com/leobaro/datacomp/1ppac67y/config.yaml?Expires=1736949037&GoogleAccessId=gorilla-files-url-signer-man%40wandb-production.iam.gserviceaccount.com&Signature=bSto9X6Yu01QYGLcQoa%2FynccrCIUBbFBGgz1wSE5jkgjj2disErKVQYteWgyETzaVcKQBvNv0mmlhSKkico50VHkeTn78RFW%2FjFD6MtwmFauSceOqyresu8VJOS%2F9Ftqbx7D3vACtjQBomGH82FMbRGOuIO7XLz4%2F55PFi74XFZAkmkiXwytrx1vYfvum161iO2KVyTwA545ZY2ez%2FadM77%2FILcNgchtPrynQnLg%2BV0ejr9LfgguAunHnKQU7ko02UNotRLTDxFLvQ3e70suP7IiX6EtDIp9OqW70EeKL45Qx51gXoulkD7alkNZ7FtKczEui6FTvlI1XJ75xiIGCw%3D%3D: ('Connection aborted.', ConnectionResetError(104, 'Connection reset by peer'))
2025-01-14 14:53:24,298 ERROR   Thread-9  :37540 [internal_api.py:upload_file():1696] upload_file request headers: {'User-Agent': 'python-requests/2.28.1', 'Accept-Encoding': 'gzip, deflate', 'Accept': '*/*', 'Connection': 'keep-alive', 'Content-Length': '2106'}
2025-01-14 14:53:24,298 ERROR   Thread-9  :37540 [internal_api.py:upload_file():1698] upload_file response body: 
2025-01-14 14:54:40,510 INFO    Thread-9  :37540 [upload_job.py:push():138] Uploaded file /home/leobaro/workspace/labs/fair_spoke_8/fair_spoke_8_leonardo/datacomp_download/wandb/run-20250114_144901-1ppac67y/files/config.yaml
2025-01-14 14:54:40,951 INFO    MainThread:37540 [internal.py:handle_exit():80] Internal process exited
